Workbook

Sheet ChemicalList
A1: Order No. | B1: Order Date | C1: Ordered By | D1: Product Name | E1: Manufacturer | F1: Package Size | G1: CAS No. | H1: Catalog No. | I1: Room | J1: Storage Temp. | K1: Cabinet | L1: Quantity | M1: Used | N1: Status | O1: Remarks | P1: Sensitivity | Q1: Signal Word | R1: Key Hazards | S1: Detailed Hazard Classification | T1: Detail_Link | U1: SDS_Link | V1: Original Product Name
A2: 26-0063 | B2: 2/4 | C2: 김민수 | D2: =IF(OR(E2="", H2=""), V2, IFERROR(IF(VLOOKUP(E2&"|"&H2&"", DB!$A:$N, 4, FALSE)="", V2, VLOOKUP(E2&"|"&H2&"", DB!$A:$N, 4, FALSE)), V2)) -> Perfluorooctane | E2: Aldrich | F2: 100 g | G2: =IF(OR(E2="", H2=""), "", IFERROR(VLOOKUP(E2&"|"&H2&"", DB!$A:$N, 5, FALSE), "")) -> 307-34-6 | H2: 359238 | I2: 309 | J2: =IFERROR(IF(OR(VLOOKUP(E2&"|"&H2&"", DB!$A:$N, 6, FALSE)="", VLOOKUP(E2&"|"&H2&"", DB!$A:$N, 6, FALSE)="-"), "", VLOOKUP(E2&"|"&H2&"", DB!$A:$N, 6, FALSE)), "") -> RT | K2: Ra1 | L2: 1 | N2: =IF(TRIM(D2)="", "", IF(N(L2)-N(M2)<=0, "X", N(L2)-N(M2))) -> 1 | P2: =IF(OR(E2="", H2=""), "", IFERROR(IF(VLOOKUP(E2&"|"&H2&"", DB!$A:$N, 7, FALSE)="","-",VLOOKUP(E2&"|"&H2&"", DB!$A:$N, 7, FALSE)), "-")) -> - | Q2: =IF(OR(E2="", H2=""), "", IFERROR(IF(VLOOKUP(E2&"|"&H2&"", DB!$A:$N, 8, FALSE)="","-",VLOOKUP(E2&"|"&H2&"", DB!$A:$N, 8, FALSE)), "-")) -> - | R2: =IF(OR(E2="", H2=""), "", IFERROR(IF(VLOOKUP(E2&"|"&H2&"", DB!$A:$N, 9, FALSE)="","-",VLOOKUP(E2&"|"&H2&"", DB!$A:$N, 9, FALSE)), "-")) -> - | S2: =IF(OR(E2="", H2=""), "", IFERROR(IF(VLOOKUP(E2&"|"&H2&"", DB!$A:$N, 10, FALSE)="","-",VLOOKUP(E2&"|"&H2&"", DB!$A:$N, 10, FALSE)), "-")) -> - | T2: =IF(OR(E2="", H2=""), "", IFERROR(IF(VLOOKUP(E2&"|"&H2&"", DB!$A:$N, 11, FALSE)="","-",VLOOKUP(E2&"|"&H2&"", DB!$A:$N, 11, FALSE)), "-")) -> https://www.sigmaaldrich.com/KR/en/product/aldrich/359238 | U2: =IF(OR(E2="", H2=""), "", IFERROR(IF(VLOOKUP(E2&"|"&H2&"", DB!$A:$N, 12, FALSE)="","-",VLOOKUP(E2&"|"&H2&"", DB!$A:$N, 12, FALSE)), "-")) -> https://www.sigmaaldrich.com/KR/ko/sds/aldrich/359238 | V2: Perfluorooctane
D3: =IF(OR(E3="", H3=""), V3, IFERROR(IF(VLOOKUP(E3&"|"&H3&"", DB!$A:$N, 4, FALSE)="", V3, VLOOKUP(E3&"|"&H3&"", DB!$A:$N, 4, FALSE)), V3)) -> (3-Aminopropyl)triethoxysilane | E3: Aldrich | F3: 100 mL | G3: =IF(OR(E3="", H3=""), "", IFERROR(VLOOKUP(E3&"|"&H3&"", DB!$A:$N, 5, FALSE), "")) -> 919-30-2 | H3: 440140 | I3: 1018 | J3: =IFERROR(IF(OR(VLOOKUP(E3&"|"&H3&"", DB!$A:$N, 6, FALSE)="", VLOOKUP(E3&"|"&H3&"", DB!$A:$N, 6, FALSE)="-"), "", VLOOKUP(E3&"|"&H3&"", DB!$A:$N, 6, FALSE)), "") | K3: Fa1 | L3: 1 | N3: =IF(TRIM(D3)="", "", IF(N(L3)-N(M3)<=0, "X", N(L3)-N(M3))) -> 1 | P3: =IF(OR(E3="", H3=""), "", IFERROR(IF(VLOOKUP(E3&"|"&H3&"", DB!$A:$N, 7, FALSE)="","-",VLOOKUP(E3&"|"&H3&"", DB!$A:$N, 7, FALSE)), "-")) -> - | Q3: =IF(OR(E3="", H3=""), "", IFERROR(IF(VLOOKUP(E3&"|"&H3&"", DB!$A:$N, 8, FALSE)="","-",VLOOKUP(E3&"|"&H3&"", DB!$A:$N, 8, FALSE)), "-")) -> ● Danger | R3: =IF(OR(E3="", H3=""), "", IFERROR(IF(VLOOKUP(E3&"|"&H3&"", DB!$A:$N, 9, FALSE)="","-",VLOOKUP(E3&"|"&H3&"", DB!$A:$N, 9, FALSE)), "-")) -> ▲ Corrosive / Eye Damage | S3: =IF(OR(E3="", H3=""), "", IFERROR(IF(VLOOKUP(E3&"|"&H3&"", DB!$A:$N, 10, FALSE)="","-",VLOOKUP(E3&"|"&H3&"", DB!$A:$N, 10, FALSE)), "-")) -> H314: Causes severe skin burns and eye damage / H317: May cause an allergic skin reaction / H302: Harmful if swallowed | T3: =IF(OR(E3="", H3=""), "", IFERROR(IF(VLOOKUP(E3&"|"&H3&"", DB!$A:$N, 11, FALSE)="","-",VLOOKUP(E3&"|"&H3&"", DB!$A:$N, 11, FALSE)), "-")) -> https://www.sigmaaldrich.com/KR/en/product/aldrich/440140 | U3: =IF(OR(E3="", H3=""), "", IFERROR(IF(VLOOKUP(E3&"|"&H3&"", DB!$A:$N, 12, FALSE)="","-",VLOOKUP(E3&"|"&H3&"", DB!$A:$N, 12, FALSE)), "-")) -> https://www.sigmaaldrich.com/KR/ko/sds/aldrich/440140 | V3: (3-Aminopropyl)triethoxysilane
A4: 26-0043 | B4: 1/28 | C4: 초오 | D4: =IF(OR(E4="", H4=""), V4, IFERROR(IF(VLOOKUP(E4&"|"&H4&"", DB!$A:$N, 4, FALSE)="", V4, VLOOKUP(E4&"|"&H4&"", DB!$A:$N, 4, FALSE)), V4)) -> [ab213480] Anti-PD-L1 antibody | G4: =IF(OR(E4="", H4=""), "", IFERROR(VLOOKUP(E4&"|"&H4&"", DB!$A:$N, 5, FALSE), "")) | I4: 1018 | J4: =IF(OR(TRIM(E4)="", TRIM(H4)=""), "", IFERROR(IF(OR(VLOOKUP(E4&"|"&H4&"", DB!$A:$N, 6, FALSE)="", VLOOKUP(E4&"|"&H4&"", DB!$A:$N, 6, FALSE)="-"), "", VLOOKUP(E4&"|"&H4&"", DB!$A:$N, 6, FALSE)), "")) | K4: Ca1 | M4: 1 | N4: =IF(TRIM(D4)="", "", IF(N(L4)-N(M4)<=0, "X", N(L4)-N(M4))) -> X | V4: [ab213480] Anti-PD-L1 antibody
C5: 윤벼리 | D5: =IF(OR(E5="", H5=""), V5, IFERROR(IF(VLOOKUP(E5&"|"&H5&"", DB!$A:$N, 4, FALSE)="", V5, VLOOKUP(E5&"|"&H5&"", DB!$A:$N, 4, FALSE)), V5)) -> [ab76003] Anti-MMP9 antibody [EP1254] | E5: Aa | F5: 1 | G5: =IF(OR(E5="", H5=""), "", IFERROR(VLOOKUP(E5&"|"&H5&"", DB!$A:$N, 5, FALSE), "")) | I5: 1001 | J5: =IF(OR(TRIM(E5)="", TRIM(H5)=""), "", IFERROR(IF(OR(VLOOKUP(E5&"|"&H5&"", DB!$A:$N, 6, FALSE)="", VLOOKUP(E5&"|"&H5&"", DB!$A:$N, 6, FALSE)="-"), "", VLOOKUP(E5&"|"&H5&"", DB!$A:$N, 6, FALSE)), "")) | K5: Ca2 | L5: 2 | N5: =IF(TRIM(D5)="", "", IF(N(L5)-N(M5)<=0, "X", N(L5)-N(M5))) -> 2 | P5: =IF(OR(E5="", H5=""), "", IFERROR(IF(VLOOKUP(E5&"|"&H5&"", DB!$A:$N, 7, FALSE)="","-",VLOOKUP(E5&"|"&H5&"", DB!$A:$N, 7, FALSE)), "-")) | Q5: =IF(OR(E5="", H5=""), "", IFERROR(IF(VLOOKUP(E5&"|"&H5&"", DB!$A:$N, 8, FALSE)="","-",VLOOKUP(E5&"|"&H5&"", DB!$A:$N, 8, FALSE)), "-")) | R5: =IF(OR(E5="", H5=""), "", IFERROR(IF(VLOOKUP(E5&"|"&H5&"", DB!$A:$N, 9, FALSE)="","-",VLOOKUP(E5&"|"&H5&"", DB!$A:$N, 9, FALSE)), "-")) | S5: =IF(OR(E5="", H5=""), "", IFERROR(IF(VLOOKUP(E5&"|"&H5&"", DB!$A:$N, 10, FALSE)="","-",VLOOKUP(E5&"|"&H5&"", DB!$A:$N, 10, FALSE)), "-")) | T5: =IF(OR(E5="", H5=""), "", IFERROR(IF(VLOOKUP(E5&"|"&H5&"", DB!$A:$N, 11, FALSE)="","-",VLOOKUP(E5&"|"&H5&"", DB!$A:$N, 11, FALSE)), "-")) | U5: =IF(OR(E5="", H5=""), "", IFERROR(IF(VLOOKUP(E5&"|"&H5&"", DB!$A:$N, 12, FALSE)="","-",VLOOKUP(E5&"|"&H5&"", DB!$A:$N, 12, FALSE)), "-")) | V5: [ab76003] Anti-MMP9 antibody [EP1254]
A6: 26-0057 | B6: 2/4 | C6: 윤벼리 | D6: =IF(OR(E6="", H6=""), V6, IFERROR(IF(VLOOKUP(E6&"|"&H6&"", DB!$A:$N, 4, FALSE)="", V6, VLOOKUP(E6&"|"&H6&"", DB!$A:$N, 4, FALSE)), V6)) -> [ab76003] Anti-MMP9 antibody [EP1254] | E6: Aa | F6: 1 | G6: =IF(OR(E6="", H6=""), "", IFERROR(VLOOKUP(E6&"|"&H6&"", DB!$A:$N, 5, FALSE), "")) -> Manual Input Required | H6: 1 | J6: =IFERROR(IF(OR(VLOOKUP(E6&"|"&H6&"", DB!$A:$N, 6, FALSE)="", VLOOKUP(E6&"|"&H6&"", DB!$A:$N, 6, FALSE)="-"), "", VLOOKUP(E6&"|"&H6&"", DB!$A:$N, 6, FALSE)), "") | L6: 2 | N6: =IF(TRIM(D6)="", "", IF(N(L6)-N(M6)<=0, "X", N(L6)-N(M6))) -> 2 | P6: =IF(OR(E6="", H6=""), "", IFERROR(IF(VLOOKUP(E6&"|"&H6&"", DB!$A:$N, 7, FALSE)="","-",VLOOKUP(E6&"|"&H6&"", DB!$A:$N, 7, FALSE)), "-")) -> - | Q6: =IF(OR(E6="", H6=""), "", IFERROR(IF(VLOOKUP(E6&"|"&H6&"", DB!$A:$N, 8, FALSE)="","-",VLOOKUP(E6&"|"&H6&"", DB!$A:$N, 8, FALSE)), "-")) -> - | R6: =IF(OR(E6="", H6=""), "", IFERROR(IF(VLOOKUP(E6&"|"&H6&"", DB!$A:$N, 9, FALSE)="","-",VLOOKUP(E6&"|"&H6&"", DB!$A:$N, 9, FALSE)), "-")) -> - | S6: =IF(OR(E6="", H6=""), "", IFERROR(IF(VLOOKUP(E6&"|"&H6&"", DB!$A:$N, 10, FALSE)="","-",VLOOKUP(E6&"|"&H6&"", DB!$A:$N, 10, FALSE)), "-")) -> - | T6: =IF(OR(E6="", H6=""), "", IFERROR(IF(VLOOKUP(E6&"|"&H6&"", DB!$A:$N, 11, FALSE)="","-",VLOOKUP(E6&"|"&H6&"", DB!$A:$N, 11, FALSE)), "-")) -> - | U6: =IF(OR(E6="", H6=""), "", IFERROR(IF(VLOOKUP(E6&"|"&H6&"", DB!$A:$N, 12, FALSE)="","-",VLOOKUP(E6&"|"&H6&"", DB!$A:$N, 12, FALSE)), "-")) -> - | V6: [ab76003] Anti-MMP9 antibody [EP1254]
C7: 초오 | D7: =IF(OR(E7="", H7=""), V7, IFERROR(IF(VLOOKUP(E7&"|"&H7&"", DB!$A:$N, 4, FALSE)="", V7, VLOOKUP(E7&"|"&H7&"", DB!$A:$N, 4, FALSE)), V7)) -> [B7651] Brefeldin A | E7: Fff | F7: a | G7: =IF(OR(E7="", H7=""), "", IFERROR(VLOOKUP(E7&"|"&H7&"", DB!$A:$N, 5, FALSE), "")) | I7: 1018 | J7: =IF(OR(TRIM(E7)="", TRIM(H7)=""), "", IFERROR(IF(OR(VLOOKUP(E7&"|"&H7&"", DB!$A:$N, 6, FALSE)="", VLOOKUP(E7&"|"&H7&"", DB!$A:$N, 6, FALSE)="-"), "", VLOOKUP(E7&"|"&H7&"", DB!$A:$N, 6, FALSE)), "")) | K7: Db2 | L7: 2 | M7: 1 | N7: =IF(TRIM(D7)="", "", IF(N(L7)-N(M7)<=0, "X", N(L7)-N(M7))) -> 1 | P7: =IF(OR(E7="", H7=""), "", IFERROR(IF(VLOOKUP(E7&"|"&H7&"", DB!$A:$N, 7, FALSE)="","-",VLOOKUP(E7&"|"&H7&"", DB!$A:$N, 7, FALSE)), "-")) | Q7: =IF(OR(E7="", H7=""), "", IFERROR(IF(VLOOKUP(E7&"|"&H7&"", DB!$A:$N, 8, FALSE)="","-",VLOOKUP(E7&"|"&H7&"", DB!$A:$N, 8, FALSE)), "-")) | R7: =IF(OR(E7="", H7=""), "", IFERROR(IF(VLOOKUP(E7&"|"&H7&"", DB!$A:$N, 9, FALSE)="","-",VLOOKUP(E7&"|"&H7&"", DB!$A:$N, 9, FALSE)), "-")) | S7: =IF(OR(E7="", H7=""), "", IFERROR(IF(VLOOKUP(E7&"|"&H7&"", DB!$A:$N, 10, FALSE)="","-",VLOOKUP(E7&"|"&H7&"", DB!$A:$N, 10, FALSE)), "-")) | T7: =IF(OR(E7="", H7=""), "", IFERROR(IF(VLOOKUP(E7&"|"&H7&"", DB!$A:$N, 11, FALSE)="","-",VLOOKUP(E7&"|"&H7&"", DB!$A:$N, 11, FALSE)), "-")) | U7: =IF(OR(E7="", H7=""), "", IFERROR(IF(VLOOKUP(E7&"|"&H7&"", DB!$A:$N, 12, FALSE)="","-",VLOOKUP(E7&"|"&H7&"", DB!$A:$N, 12, FALSE)), "-")) | V7: [B7651] Brefeldin A
A8: 26-0040 | B8: 1/26 | C8: 초오 | D8: =IF(OR(E8="", H8=""), V8, IFERROR(IF(VLOOKUP(E8&"|"&H8&"", DB!$A:$N, 4, FALSE)="", V8, VLOOKUP(E8&"|"&H8&"", DB!$A:$N, 4, FALSE)), V8)) -> [B7651] Brefeldin A | E8: Fff | F8: a | G8: =IF(OR(E8="", H8=""), "", IFERROR(VLOOKUP(E8&"|"&H8&"", DB!$A:$N, 5, FALSE), "")) -> Manual Input Required | H8: 2w5w | J8: =IFERROR(IF(OR(VLOOKUP(E8&"|"&H8&"", DB!$A:$N, 6, FALSE)="", VLOOKUP(E8&"|"&H8&"", DB!$A:$N, 6, FALSE)="-"), "", VLOOKUP(E8&"|"&H8&"", DB!$A:$N, 6, FALSE)), "") | L8: 2 | N8: =IF(TRIM(D8)="", "", IF(N(L8)-N(M8)<=0, "X", N(L8)-N(M8))) -> 2 | P8: =IF(OR(E8="", H8=""), "", IFERROR(IF(VLOOKUP(E8&"|"&H8&"", DB!$A:$N, 7, FALSE)="","-",VLOOKUP(E8&"|"&H8&"", DB!$A:$N, 7, FALSE)), "-")) -> - | Q8: =IF(OR(E8="", H8=""), "", IFERROR(IF(VLOOKUP(E8&"|"&H8&"", DB!$A:$N, 8, FALSE)="","-",VLOOKUP(E8&"|"&H8&"", DB!$A:$N, 8, FALSE)), "-")) -> - | R8: =IF(OR(E8="", H8=""), "", IFERROR(IF(VLOOKUP(E8&"|"&H8&"", DB!$A:$N, 9, FALSE)="","-",VLOOKUP(E8&"|"&H8&"", DB!$A:$N, 9, FALSE)), "-")) -> - | S8: =IF(OR(E8="", H8=""), "", IFERROR(IF(VLOOKUP(E8&"|"&H8&"", DB!$A:$N, 10, FALSE)="","-",VLOOKUP(E8&"|"&H8&"", DB!$A:$N, 10, FALSE)), "-")) -> - | T8: =IF(OR(E8="", H8=""), "", IFERROR(IF(VLOOKUP(E8&"|"&H8&"", DB!$A:$N, 11, FALSE)="","-",VLOOKUP(E8&"|"&H8&"", DB!$A:$N, 11, FALSE)), "-")) -> - | U8: =IF(OR(E8="", H8=""), "", IFERROR(IF(VLOOKUP(E8&"|"&H8&"", DB!$A:$N, 12, FALSE)="","-",VLOOKUP(E8&"|"&H8&"", DB!$A:$N, 12, FALSE)), "-")) -> - | V8: [B7651] Brefeldin A
A9: 26-0038 | B9: 1/26 | C9: 초오 | D9: =IF(OR(E9="", H9=""), V9, IFERROR(IF(VLOOKUP(E9&"|"&H9&"", DB!$A:$N, 4, FALSE)="", V9, VLOOKUP(E9&"|"&H9&"", DB!$A:$N, 4, FALSE)), V9)) -> [B7651] Brefeldin A | E9: Fff | F9: a | G9: =IF(OR(E9="", H9=""), "", IFERROR(VLOOKUP(E9&"|"&H9&"", DB!$A:$N, 5, FALSE), "")) -> Manual Input Required | H9: 2w5w | I9: 1018 | J9: =IFERROR(IF(OR(VLOOKUP(E9&"|"&H9&"", DB!$A:$N, 6, FALSE)="", VLOOKUP(E9&"|"&H9&"", DB!$A:$N, 6, FALSE)="-"), "", VLOOKUP(E9&"|"&H9&"", DB!$A:$N, 6, FALSE)), "") | K9: Ca2 | L9: 2 | N9: =IF(TRIM(D9)="", "", IF(N(L9)-N(M9)<=0, "X", N(L9)-N(M9))) -> 2 | P9: =IF(OR(E9="", H9=""), "", IFERROR(IF(VLOOKUP(E9&"|"&H9&"", DB!$A:$N, 7, FALSE)="","-",VLOOKUP(E9&"|"&H9&"", DB!$A:$N, 7, FALSE)), "-")) -> - | Q9: =IF(OR(E9="", H9=""), "", IFERROR(IF(VLOOKUP(E9&"|"&H9&"", DB!$A:$N, 8, FALSE)="","-",VLOOKUP(E9&"|"&H9&"", DB!$A:$N, 8, FALSE)), "-")) -> - | R9: =IF(OR(E9="", H9=""), "", IFERROR(IF(VLOOKUP(E9&"|"&H9&"", DB!$A:$N, 9, FALSE)="","-",VLOOKUP(E9&"|"&H9&"", DB!$A:$N, 9, FALSE)), "-")) -> - | S9: =IF(OR(E9="", H9=""), "", IFERROR(IF(VLOOKUP(E9&"|"&H9&"", DB!$A:$N, 10, FALSE)="","-",VLOOKUP(E9&"|"&H9&"", DB!$A:$N, 10, FALSE)), "-")) -> - | T9: =IF(OR(E9="", H9=""), "", IFERROR(IF(VLOOKUP(E9&"|"&H9&"", DB!$A:$N, 11, FALSE)="","-",VLOOKUP(E9&"|"&H9&"", DB!$A:$N, 11, FALSE)), "-")) -> - | U9: =IF(OR(E9="", H9=""), "", IFERROR(IF(VLOOKUP(E9&"|"&H9&"", DB!$A:$N, 12, FALSE)="","-",VLOOKUP(E9&"|"&H9&"", DB!$A:$N, 12, FALSE)), "-")) -> - | V9: [B7651] Brefeldin A
C10: 초오 | D10: =IF(OR(E10="", H10=""), V10, IFERROR(IF(VLOOKUP(E10&"|"&H10&"", DB!$A:$N, 4, FALSE)="", V10, VLOOKUP(E10&"|"&H10&"", DB!$A:$N, 4, FALSE)), V10)) -> [S0809.5000] Sucrose | G10: =IF(OR(E10="", H10=""), "", IFERROR(VLOOKUP(E10&"|"&H10&"", DB!$A:$N, 5, FALSE), "")) | I10: 1001 | J10: =IF(OR(TRIM(E10)="", TRIM(H10)=""), "", IFERROR(IF(OR(VLOOKUP(E10&"|"&H10&"", DB!$A:$N, 6, FALSE)="", VLOOKUP(E10&"|"&H10&"", DB!$A:$N, 6, FALSE)="-"), "", VLOOKUP(E10&"|"&H10&"", DB!$A:$N, 6, FALSE)), "")) | K10: Da1 | N10: =IF(TRIM(D10)="", "", IF(N(L10)-N(M10)<=0, "X", N(L10)-N(M10))) -> X | V10: [S0809.5000] Sucrose
A11: 26-0049 | B11: 1/29 | C11: 초오 | D11: =IF(OR(E11="", H11=""), V11, IFERROR(IF(VLOOKUP(E11&"|"&H11&"", DB!$A:$N, 4, FALSE)="", V11, VLOOKUP(E11&"|"&H11&"", DB!$A:$N, 4, FALSE)), V11)) -> [S0809.5000] Sucrose | G11: =IF(OR(E11="", H11=""), "", IFERROR(VLOOKUP(E11&"|"&H11&"", DB!$A:$N, 5, FALSE), "")) | J11: =IF(OR(TRIM(E11)="", TRIM(H11)=""), "", IFERROR(IF(OR(VLOOKUP(E11&"|"&H11&"", DB!$A:$N, 6, FALSE)="", VLOOKUP(E11&"|"&H11&"", DB!$A:$N, 6, FALSE)="-"), "", VLOOKUP(E11&"|"&H11&"", DB!$A:$N, 6, FALSE)), "")) | L11: 2 | M11: 2 | N11: =IF(TRIM(D11)="", "", IF(N(L11)-N(M11)<=0, "X", N(L11)-N(M11))) -> X | V11: [S0809.5000] Sucrose
D12: =IF(OR(E12="", H12=""), V12, IFERROR(IF(VLOOKUP(E12&"|"&H12&"", DB!$A:$N, 4, FALSE)="", V12, VLOOKUP(E12&"|"&H12&"", DB!$A:$N, 4, FALSE)), V12)) -> 0.1 M Disodium hydrogenphos | G12: =IF(OR(E12="", H12=""), "", IFERROR(VLOOKUP(E12&"|"&H12&"", DB!$A:$N, 5, FALSE), "")) | I12: 309 | J12: =IF(OR(TRIM(E12)="", TRIM(H12)=""), "", IFERROR(IF(OR(VLOOKUP(E12&"|"&H12&"", DB!$A:$N, 6, FALSE)="", VLOOKUP(E12&"|"&H12&"", DB!$A:$N, 6, FALSE)="-"), "", VLOOKUP(E12&"|"&H12&"", DB!$A:$N, 6, FALSE)), "")) | K12: Da1 | L12: 1 | N12: =IF(TRIM(D12)="", "", IF(N(L12)-N(M12)<=0, "X", N(L12)-N(M12))) -> 1 | V12: 0.1 M Disodium hydrogenphos
D13: =IF(OR(E13="", H13=""), V13, IFERROR(IF(VLOOKUP(E13&"|"&H13&"", DB!$A:$N, 4, FALSE)="", V13, VLOOKUP(E13&"|"&H13&"", DB!$A:$N, 4, FALSE)), V13)) -> 0.1 M Sodium phosphate | E13: Made By Nki | G13: =IF(OR(E13="", H13=""), "", IFERROR(VLOOKUP(E13&"|"&H13&"", DB!$A:$N, 5, FALSE), "")) | I13: 1018 | J13: =IF(OR(TRIM(E13)="", TRIM(H13)=""), "", IFERROR(IF(OR(VLOOKUP(E13&"|"&H13&"", DB!$A:$N, 6, FALSE)="", VLOOKUP(E13&"|"&H13&"", DB!$A:$N, 6, FALSE)="-"), "", VLOOKUP(E13&"|"&H13&"", DB!$A:$N, 6, FALSE)), "")) | K13: Ra1 | L13: 1 | N13: =IF(TRIM(D13)="", "", IF(N(L13)-N(M13)<=0, "X", N(L13)-N(M13))) -> 1 | V13: 0.1 M Sodium phosphate
D14: =IF(OR(E14="", H14=""), V14, IFERROR(IF(VLOOKUP(E14&"|"&H14&"", DB!$A:$N, 4, FALSE)="", V14, VLOOKUP(E14&"|"&H14&"", DB!$A:$N, 4, FALSE)), V14)) -> 33 | E14: Aldrich | F14: 100 mL | G14: =IF(OR(E14="", H14=""), "", IFERROR(VLOOKUP(E14&"|"&H14&"", DB!$A:$N, 5, FALSE), "")) | I14: 309 | J14: =IF(OR(TRIM(E14)="", TRIM(H14)=""), "", IFERROR(IF(OR(VLOOKUP(E14&"|"&H14&"", DB!$A:$N, 6, FALSE)="", VLOOKUP(E14&"|"&H14&"", DB!$A:$N, 6, FALSE)="-"), "", VLOOKUP(E14&"|"&H14&"", DB!$A:$N, 6, FALSE)), "")) | K14: Da1 | L14: 1 | N14: =IF(TRIM(D14)="", "", IF(N(L14)-N(M14)<=0, "X", N(L14)-N(M14))) -> 1 | P14: =IF(OR(E14="", H14=""), "", IFERROR(IF(VLOOKUP(E14&"|"&H14&"", DB!$A:$N, 7, FALSE)="","-",VLOOKUP(E14&"|"&H14&"", DB!$A:$N, 7, FALSE)), "-")) | Q14: =IF(OR(E14="", H14=""), "", IFERROR(IF(VLOOKUP(E14&"|"&H14&"", DB!$A:$N, 8, FALSE)="","-",VLOOKUP(E14&"|"&H14&"", DB!$A:$N, 8, FALSE)), "-")) | R14: =IF(OR(E14="", H14=""), "", IFERROR(IF(VLOOKUP(E14&"|"&H14&"", DB!$A:$N, 9, FALSE)="","-",VLOOKUP(E14&"|"&H14&"", DB!$A:$N, 9, FALSE)), "-")) | S14: =IF(OR(E14="", H14=""), "", IFERROR(IF(VLOOKUP(E14&"|"&H14&"", DB!$A:$N, 10, FALSE)="","-",VLOOKUP(E14&"|"&H14&"", DB!$A:$N, 10, FALSE)), "-")) | T14: =IF(OR(E14="", H14=""), "", IFERROR(IF(VLOOKUP(E14&"|"&H14&"", DB!$A:$N, 11, FALSE)="","-",VLOOKUP(E14&"|"&H14&"", DB!$A:$N, 11, FALSE)), "-")) | U14: =IF(OR(E14="", H14=""), "", IFERROR(IF(VLOOKUP(E14&"|"&H14&"", DB!$A:$N, 12, FALSE)="","-",VLOOKUP(E14&"|"&H14&"", DB!$A:$N, 12, FALSE)), "-")) | V14: 33
D15: =IF(OR(E15="", H15=""), V15, IFERROR(IF(VLOOKUP(E15&"|"&H15&"", DB!$A:$N, 4, FALSE)="", V15, VLOOKUP(E15&"|"&H15&"", DB!$A:$N, 4, FALSE)), V15)) -> 1,10-Phenanthroline | E15: Aldrich | F15: 5 g | G15: =IF(OR(E15="", H15=""), "", IFERROR(VLOOKUP(E15&"|"&H15&"", DB!$A:$N, 5, FALSE), "")) -> 66-71-7 | H15: 131377 | I15: 1018 | J15: =IFERROR(IF(OR(VLOOKUP(E15&"|"&H15&"", DB!$A:$N, 6, FALSE)="", VLOOKUP(E15&"|"&H15&"", DB!$A:$N, 6, FALSE)="-"), "", VLOOKUP(E15&"|"&H15&"", DB!$A:$N, 6, FALSE)), "") | K15: Db2 | L15: 1 | N15: =IF(TRIM(D15)="", "", IF(N(L15)-N(M15)<=0, "X", N(L15)-N(M15))) -> 1 | P15: =IF(OR(E15="", H15=""), "", IFERROR(IF(VLOOKUP(E15&"|"&H15&"", DB!$A:$N, 7, FALSE)="","-",VLOOKUP(E15&"|"&H15&"", DB!$A:$N, 7, FALSE)), "-")) -> - | Q15: =IF(OR(E15="", H15=""), "", IFERROR(IF(VLOOKUP(E15&"|"&H15&"", DB!$A:$N, 8, FALSE)="","-",VLOOKUP(E15&"|"&H15&"", DB!$A:$N, 8, FALSE)), "-")) -> - | R15: =IF(OR(E15="", H15=""), "", IFERROR(IF(VLOOKUP(E15&"|"&H15&"", DB!$A:$N, 9, FALSE)="","-",VLOOKUP(E15&"|"&H15&"", DB!$A:$N, 9, FALSE)), "-")) -> ● Toxic, ■ Environmental Hazard | S15: =IF(OR(E15="", H15=""), "", IFERROR(IF(VLOOKUP(E15&"|"&H15&"", DB!$A:$N, 10, FALSE)="","-",VLOOKUP(E15&"|"&H15&"", DB!$A:$N, 10, FALSE)), "-")) -> H410: Very toxic to aquatic life with long lasting effects / H301: Toxic if swallowed | T15: =IF(OR(E15="", H15=""), "", IFERROR(IF(VLOOKUP(E15&"|"&H15&"", DB!$A:$N, 11, FALSE)="","-",VLOOKUP(E15&"|"&H15&"", DB!$A:$N, 11, FALSE)), "-")) -> https://www.sigmaaldrich.com/KR/en/product/aldrich/131377 | U15: =IF(OR(E15="", H15=""), "", IFERROR(IF(VLOOKUP(E15&"|"&H15&"", DB!$A:$N, 12, FALSE)="","-",VLOOKUP(E15&"|"&H15&"", DB!$A:$N, 12, FALSE)), "-")) -> https://www.sigmaaldrich.com/KR/ko/sds/aldrich/131377 | V15: 1,10-Phenanthroline
A16: 26-0465 | B16: 7/20 | C16: 윤벼리 | D16: =IF(OR(E16="", H16=""), V16, IFERROR(IF(VLOOKUP(E16&"|"&H16&"", DB!$A:$N, 4, FALSE)="", V16, VLOOKUP(E16&"|"&H16&"", DB!$A:$N, 4, FALSE)), V16)) -> Acrylamide | G16: =IF(OR(E16="", H16=""), "", IFERROR(VLOOKUP(E16&"|"&H16&"", DB!$A:$N, 5, FALSE), "")) | J16: =IF(OR(TRIM(E16)="", TRIM(H16)=""), "", IFERROR(IF(OR(VLOOKUP(E16&"|"&H16&"", DB!$A:$N, 6, FALSE)="", VLOOKUP(E16&"|"&H16&"", DB!$A:$N, 6, FALSE)="-"), "", VLOOKUP(E16&"|"&H16&"", DB!$A:$N, 6, FALSE)), "")) | N16: =IF(TRIM(D16)="", "", IF(N(L16)-N(M16)<=0, "X", N(L16)-N(M16))) -> X | V16: Acrylamide
C17: 김민수 | D17: =IF(OR(E17="", H17=""), V17, IFERROR(IF(VLOOKUP(E17&"|"&H17&"", DB!$A:$N, 4, FALSE)="", V17, VLOOKUP(E17&"|"&H17&"", DB!$A:$N, 4, FALSE)), V17)) -> Alexa Fluor® 488 anti- mouse CD4 Antibody | G17: =IF(OR(E17="", H17=""), "", IFERROR(VLOOKUP(E17&"|"&H17&"", DB!$A:$N, 5, FALSE), "")) | I17: 1001 | J17: =IF(OR(TRIM(E17)="", TRIM(H17)=""), "", IFERROR(IF(OR(VLOOKUP(E17&"|"&H17&"", DB!$A:$N, 6, FALSE)="", VLOOKUP(E17&"|"&H17&"", DB!$A:$N, 6, FALSE)="-"), "", VLOOKUP(E17&"|"&H17&"", DB!$A:$N, 6, FALSE)), "")) | K17: Ra1 | N17: =IF(TRIM(D17)="", "", IF(N(L17)-N(M17)<=0, "X", N(L17)-N(M17))) -> X | V17: Alexa Fluor® 488 anti- mouse CD4 Antibody
A18: 26-0125 | B18: 3/5 | C18: 김민수 | D18: =IF(OR(E18="", H18=""), V18, IFERROR(IF(VLOOKUP(E18&"|"&H18&"", DB!$A:$N, 4, FALSE)="", V18, VLOOKUP(E18&"|"&H18&"", DB!$A:$N, 4, FALSE)), V18)) -> Alexa Fluor® 488 anti- mouse CD4 Antibody | G18: =IF(OR(E18="", H18=""), "", IFERROR(VLOOKUP(E18&"|"&H18&"", DB!$A:$N, 5, FALSE), "")) | J18: =IF(OR(TRIM(E18)="", TRIM(H18)=""), "", IFERROR(IF(OR(VLOOKUP(E18&"|"&H18&"", DB!$A:$N, 6, FALSE)="", VLOOKUP(E18&"|"&H18&"", DB!$A:$N, 6, FALSE)="-"), "", VLOOKUP(E18&"|"&H18&"", DB!$A:$N, 6, FALSE)), "")) | N18: =IF(TRIM(D18)="", "", IF(N(L18)-N(M18)<=0, "X", N(L18)-N(M18))) -> X | V18: Alexa Fluor® 488 anti- mouse CD4 Antibody
C19: 이지 | D19: =IF(OR(E19="", H19=""), V19, IFERROR(IF(VLOOKUP(E19&"|"&H19&"", DB!$A:$N, 4, FALSE)="", V19, VLOOKUP(E19&"|"&H19&"", DB!$A:$N, 4, FALSE)), V19)) -> bb | E19: Aldrich | F19: 13g | G19: =IF(OR(E19="", H19=""), "", IFERROR(VLOOKUP(E19&"|"&H19&"", DB!$A:$N, 5, FALSE), "")) | I19: 309 | J19: =IF(OR(TRIM(E19)="", TRIM(H19)=""), "", IFERROR(IF(OR(VLOOKUP(E19&"|"&H19&"", DB!$A:$N, 6, FALSE)="", VLOOKUP(E19&"|"&H19&"", DB!$A:$N, 6, FALSE)="-"), "", VLOOKUP(E19&"|"&H19&"", DB!$A:$N, 6, FALSE)), "")) | K19: Da1 | L19: 4 | N19: =IF(TRIM(D19)="", "", IF(N(L19)-N(M19)<=0, "X", N(L19)-N(M19))) -> 4 | P19: =IF(OR(E19="", H19=""), "", IFERROR(IF(VLOOKUP(E19&"|"&H19&"", DB!$A:$N, 7, FALSE)="","-",VLOOKUP(E19&"|"&H19&"", DB!$A:$N, 7, FALSE)), "-")) | Q19: =IF(OR(E19="", H19=""), "", IFERROR(IF(VLOOKUP(E19&"|"&H19&"", DB!$A:$N, 8, FALSE)="","-",VLOOKUP(E19&"|"&H19&"", DB!$A:$N, 8, FALSE)), "-")) | R19: =IF(OR(E19="", H19=""), "", IFERROR(IF(VLOOKUP(E19&"|"&H19&"", DB!$A:$N, 9, FALSE)="","-",VLOOKUP(E19&"|"&H19&"", DB!$A:$N, 9, FALSE)), "-")) | S19: =IF(OR(E19="", H19=""), "", IFERROR(IF(VLOOKUP(E19&"|"&H19&"", DB!$A:$N, 10, FALSE)="","-",VLOOKUP(E19&"|"&H19&"", DB!$A:$N, 10, FALSE)), "-")) | T19: =IF(OR(E19="", H19=""), "", IFERROR(IF(VLOOKUP(E19&"|"&H19&"", DB!$A:$N, 11, FALSE)="","-",VLOOKUP(E19&"|"&H19&"", DB!$A:$N, 11, FALSE)), "-")) | U19: =IF(OR(E19="", H19=""), "", IFERROR(IF(VLOOKUP(E19&"|"&H19&"", DB!$A:$N, 12, FALSE)="","-",VLOOKUP(E19&"|"&H19&"", DB!$A:$N, 12, FALSE)), "-")) | V19: bb
A20: 26-0025 | B20: 1/14 | C20: 이지 | D20: =IF(OR(E20="", H20=""), V20, IFERROR(IF(VLOOKUP(E20&"|"&H20&"", DB!$A:$N, 4, FALSE)="", V20, VLOOKUP(E20&"|"&H20&"", DB!$A:$N, 4, FALSE)), V20)) -> bb | E20: Aldrich | F20: 13g | G20: =IF(OR(E20="", H20=""), "", IFERROR(VLOOKUP(E20&"|"&H20&"", DB!$A:$N, 5, FALSE), "")) -> Search Failed | H20: 3we3 | I20: 309 | J20: =IFERROR(IF(OR(VLOOKUP(E20&"|"&H20&"", DB!$A:$N, 6, FALSE)="", VLOOKUP(E20&"|"&H20&"", DB!$A:$N, 6, FALSE)="-"), "", VLOOKUP(E20&"|"&H20&"", DB!$A:$N, 6, FALSE)), "") | K20: Ra1 | L20: 4 | N20: =IF(TRIM(D20)="", "", IF(N(L20)-N(M20)<=0, "X", N(L20)-N(M20))) -> 4 | P20: =IF(OR(E20="", H20=""), "", IFERROR(IF(VLOOKUP(E20&"|"&H20&"", DB!$A:$N, 7, FALSE)="","-",VLOOKUP(E20&"|"&H20&"", DB!$A:$N, 7, FALSE)), "-")) -> - | Q20: =IF(OR(E20="", H20=""), "", IFERROR(IF(VLOOKUP(E20&"|"&H20&"", DB!$A:$N, 8, FALSE)="","-",VLOOKUP(E20&"|"&H20&"", DB!$A:$N, 8, FALSE)), "-")) -> - | R20: =IF(OR(E20="", H20=""), "", IFERROR(IF(VLOOKUP(E20&"|"&H20&"", DB!$A:$N, 9, FALSE)="","-",VLOOKUP(E20&"|"&H20&"", DB!$A:$N, 9, FALSE)), "-")) -> - | S20: =IF(OR(E20="", H20=""), "", IFERROR(IF(VLOOKUP(E20&"|"&H20&"", DB!$A:$N, 10, FALSE)="","-",VLOOKUP(E20&"|"&H20&"", DB!$A:$N, 10, FALSE)), "-")) -> - | T20: =IF(OR(E20="", H20=""), "", IFERROR(IF(VLOOKUP(E20&"|"&H20&"", DB!$A:$N, 11, FALSE)="","-",VLOOKUP(E20&"|"&H20&"", DB!$A:$N, 11, FALSE)), "-")) -> Product Not Found | U20: =IF(OR(E20="", H20=""), "", IFERROR(IF(VLOOKUP(E20&"|"&H20&"", DB!$A:$N, 12, FALSE)="","-",VLOOKUP(E20&"|"&H20&"", DB!$A:$N, 12, FALSE)), "-")) -> - | V20: bb
A21: 26-0471 | B21: 7/21 | C21: 이정훈 | D21: =IF(OR(E21="", H21=""), V21, IFERROR(IF(VLOOKUP(E21&"|"&H21&"", DB!$A:$N, 4, FALSE)="", V21, VLOOKUP(E21&"|"&H21&"", DB!$A:$N, 4, FALSE)), V21)) -> benzalkonium chloride, 50wt% solution, 500 mL | G21: =IF(OR(E21="", H21=""), "", IFERROR(VLOOKUP(E21&"|"&H21&"", DB!$A:$N, 5, FALSE), "")) | I21: 1018 | J21: RT | K21: Ca2 | N21: =IF(TRIM(D21)="", "", IF(N(L21)-N(M21)<=0, "X", N(L21)-N(M21))) -> X | V21: benzalkonium chloride, 50wt% solution, 500 mL
C22: 김영범 | D22: =IF(OR(E22="", H22=""), V22, IFERROR(IF(VLOOKUP(E22&"|"&H22&"", DB!$A:$N, 4, FALSE)="", V22, VLOOKUP(E22&"|"&H22&"", DB!$A:$N, 4, FALSE)), V22)) -> DMEM * 40ea | G22: =IF(OR(E22="", H22=""), "", IFERROR(VLOOKUP(E22&"|"&H22&"", DB!$A:$N, 5, FALSE), "")) | I22: 1018 | J22: =IF(OR(TRIM(E22)="", TRIM(H22)=""), "", IFERROR(IF(OR(VLOOKUP(E22&"|"&H22&"", DB!$A:$N, 6, FALSE)="", VLOOKUP(E22&"|"&H22&"", DB!$A:$N, 6, FALSE)="-"), "", VLOOKUP(E22&"|"&H22&"", DB!$A:$N, 6, FALSE)), "")) | K22: Ra1 | N22: =IF(TRIM(D22)="", "", IF(N(L22)-N(M22)<=0, "X", N(L22)-N(M22))) -> X | V22: DMEM * 40ea
A23: 26-0033 | B23: 1/22 | C23: 김영범 | D23: =IF(OR(E23="", H23=""), V23, IFERROR(IF(VLOOKUP(E23&"|"&H23&"", DB!$A:$N, 4, FALSE)="", V23, VLOOKUP(E23&"|"&H23&"", DB!$A:$N, 4, FALSE)), V23)) -> DMEM * 40ea | G23: =IF(OR(E23="", H23=""), "", IFERROR(VLOOKUP(E23&"|"&H23&"", DB!$A:$N, 5, FALSE), "")) | J23: =IF(OR(TRIM(E23)="", TRIM(H23)=""), "", IFERROR(IF(OR(VLOOKUP(E23&"|"&H23&"", DB!$A:$N, 6, FALSE)="", VLOOKUP(E23&"|"&H23&"", DB!$A:$N, 6, FALSE)="-"), "", VLOOKUP(E23&"|"&H23&"", DB!$A:$N, 6, FALSE)), "")) | N23: =IF(TRIM(D23)="", "", IF(N(L23)-N(M23)<=0, "X", N(L23)-N(M23))) -> X | V23: DMEM * 40ea
A24: 26-0473 | B24: 7/22 | C24: 최희선 | D24: =IF(OR(E24="", H24=""), V24, IFERROR(IF(VLOOKUP(E24&"|"&H24&"", DB!$A:$N, 4, FALSE)="", V24, VLOOKUP(E24&"|"&H24&"", DB!$A:$N, 4, FALSE)), V24)) -> DTSSP, 3,3'-DITHIOBIS | G24: =IF(OR(E24="", H24=""), "", IFERROR(VLOOKUP(E24&"|"&H24&"", DB!$A:$N, 5, FALSE), "")) | J24: =IF(OR(TRIM(E24)="", TRIM(H24)=""), "", IFERROR(IF(OR(VLOOKUP(E24&"|"&H24&"", DB!$A:$N, 6, FALSE)="", VLOOKUP(E24&"|"&H24&"", DB!$A:$N, 6, FALSE)="-"), "", VLOOKUP(E24&"|"&H24&"", DB!$A:$N, 6, FALSE)), "")) | N24: =IF(TRIM(D24)="", "", IF(N(L24)-N(M24)<=0, "X", N(L24)-N(M24))) -> X | V24: DTSSP, 3,3'-DITHIOBIS
C25: 김영범 | D25: =IF(OR(E25="", H25=""), V25, IFERROR(IF(VLOOKUP(E25&"|"&H25&"", DB!$A:$N, 4, FALSE)="", V25, VLOOKUP(E25&"|"&H25&"", DB!$A:$N, 4, FALSE)), V25)) -> Ezatiostat 5mg | G25: =IF(OR(E25="", H25=""), "", IFERROR(VLOOKUP(E25&"|"&H25&"", DB!$A:$N, 5, FALSE), "")) | I25: 1001 | J25: =IF(OR(TRIM(E25)="", TRIM(H25)=""), "", IFERROR(IF(OR(VLOOKUP(E25&"|"&H25&"", DB!$A:$N, 6, FALSE)="", VLOOKUP(E25&"|"&H25&"", DB!$A:$N, 6, FALSE)="-"), "", VLOOKUP(E25&"|"&H25&"", DB!$A:$N, 6, FALSE)), "")) | K25: Ca2 | N25: =IF(TRIM(D25)="", "", IF(N(L25)-N(M25)<=0, "X", N(L25)-N(M25))) -> X | V25: Ezatiostat 5mg
A26: 26-0114 | B26: 3/17 | C26: 김영범 | D26: =IF(OR(E26="", H26=""), V26, IFERROR(IF(VLOOKUP(E26&"|"&H26&"", DB!$A:$N, 4, FALSE)="", V26, VLOOKUP(E26&"|"&H26&"", DB!$A:$N, 4, FALSE)), V26)) -> Ezatiostat 5mg | G26: =IF(OR(E26="", H26=""), "", IFERROR(VLOOKUP(E26&"|"&H26&"", DB!$A:$N, 5, FALSE), "")) | J26: R | N26: =IF(TRIM(D26)="", "", IF(N(L26)-N(M26)<=0, "X", N(L26)-N(M26))) -> X | V26: Ezatiostat 5mg
A27: 26-0138 | B27: 3/19 | C27: 김영범 | D27: =IF(OR(E27="", H27=""), V27, IFERROR(IF(VLOOKUP(E27&"|"&H27&"", DB!$A:$N, 4, FALSE)="", V27, VLOOKUP(E27&"|"&H27&"", DB!$A:$N, 4, FALSE)), V27)) -> Float A lyzer * 10pk | G27: =IF(OR(E27="", H27=""), "", IFERROR(VLOOKUP(E27&"|"&H27&"", DB!$A:$N, 5, FALSE), "")) | J27: =IF(OR(TRIM(E27)="", TRIM(H27)=""), "", IFERROR(IF(OR(VLOOKUP(E27&"|"&H27&"", DB!$A:$N, 6, FALSE)="", VLOOKUP(E27&"|"&H27&"", DB!$A:$N, 6, FALSE)="-"), "", VLOOKUP(E27&"|"&H27&"", DB!$A:$N, 6, FALSE)), "")) | N27: =IF(TRIM(D27)="", "", IF(N(L27)-N(M27)<=0, "X", N(L27)-N(M27))) -> X | V27: Float A lyzer * 10pk
C28: 윤벼리 | D28: =IF(OR(E28="", H28=""), V28, IFERROR(IF(VLOOKUP(E28&"|"&H28&"", DB!$A:$N, 4, FALSE)="", V28, VLOOKUP(E28&"|"&H28&"", DB!$A:$N, 4, FALSE)), V28)) -> Gelatin from porcine skin | G28: =IF(OR(E28="", H28=""), "", IFERROR(VLOOKUP(E28&"|"&H28&"", DB!$A:$N, 5, FALSE), "")) | I28: 1001 | J28: =IF(OR(TRIM(E28)="", TRIM(H28)=""), "", IFERROR(IF(OR(VLOOKUP(E28&"|"&H28&"", DB!$A:$N, 6, FALSE)="", VLOOKUP(E28&"|"&H28&"", DB!$A:$N, 6, FALSE)="-"), "", VLOOKUP(E28&"|"&H28&"", DB!$A:$N, 6, FALSE)), "")) | K28: Ca2 | N28: =IF(TRIM(D28)="", "", IF(N(L28)-N(M28)<=0, "X", N(L28)-N(M28))) -> X | V28: Gelatin from porcine skin
A29: 26-0060 | B29: 2/4 | C29: 윤벼리 | D29: =IF(OR(E29="", H29=""), V29, IFERROR(IF(VLOOKUP(E29&"|"&H29&"", DB!$A:$N, 4, FALSE)="", V29, VLOOKUP(E29&"|"&H29&"", DB!$A:$N, 4, FALSE)), V29)) -> Gelatin from porcine skin | G29: =IF(OR(E29="", H29=""), "", IFERROR(VLOOKUP(E29&"|"&H29&"", DB!$A:$N, 5, FALSE), "")) | J29: =IF(OR(TRIM(E29)="", TRIM(H29)=""), "", IFERROR(IF(OR(VLOOKUP(E29&"|"&H29&"", DB!$A:$N, 6, FALSE)="", VLOOKUP(E29&"|"&H29&"", DB!$A:$N, 6, FALSE)="-"), "", VLOOKUP(E29&"|"&H29&"", DB!$A:$N, 6, FALSE)), "")) | N29: =IF(TRIM(D29)="", "", IF(N(L29)-N(M29)<=0, "X", N(L29)-N(M29))) -> X | V29: Gelatin from porcine skin
C30: 김영범 | D30: =IF(OR(E30="", H30=""), V30, IFERROR(IF(VLOOKUP(E30&"|"&H30&"", DB!$A:$N, 4, FALSE)="", V30, VLOOKUP(E30&"|"&H30&"", DB!$A:$N, 4, FALSE)), V30)) -> Guanidine hydrochloride | G30: =IF(OR(E30="", H30=""), "", IFERROR(VLOOKUP(E30&"|"&H30&"", DB!$A:$N, 5, FALSE), "")) | I30: 309 | J30: =IF(OR(TRIM(E30)="", TRIM(H30)=""), "", IFERROR(IF(OR(VLOOKUP(E30&"|"&H30&"", DB!$A:$N, 6, FALSE)="", VLOOKUP(E30&"|"&H30&"", DB!$A:$N, 6, FALSE)="-"), "", VLOOKUP(E30&"|"&H30&"", DB!$A:$N, 6, FALSE)), "")) | K30: Ca1 | N30: =IF(TRIM(D30)="", "", IF(N(L30)-N(M30)<=0, "X", N(L30)-N(M30))) -> X | V30: Guanidine hydrochloride
A31: 26-0009 | B31: 1/9 | C31: 김영범 | D31: =IF(OR(E31="", H31=""), V31, IFERROR(IF(VLOOKUP(E31&"|"&H31&"", DB!$A:$N, 4, FALSE)="", V31, VLOOKUP(E31&"|"&H31&"", DB!$A:$N, 4, FALSE)), V31)) -> Guanidine hydrochloride | G31: =IF(OR(E31="", H31=""), "", IFERROR(VLOOKUP(E31&"|"&H31&"", DB!$A:$N, 5, FALSE), "")) | J31: =IF(OR(TRIM(E31)="", TRIM(H31)=""), "", IFERROR(IF(OR(VLOOKUP(E31&"|"&H31&"", DB!$A:$N, 6, FALSE)="", VLOOKUP(E31&"|"&H31&"", DB!$A:$N, 6, FALSE)="-"), "", VLOOKUP(E31&"|"&H31&"", DB!$A:$N, 6, FALSE)), "")) | N31: =IF(TRIM(D31)="", "", IF(N(L31)-N(M31)<=0, "X", N(L31)-N(M31))) -> X | V31: Guanidine hydrochloride
C32: 박은영 | D32: =IF(OR(E32="", H32=""), V32, IFERROR(IF(VLOOKUP(E32&"|"&H32&"", DB!$A:$N, 4, FALSE)="", V32, VLOOKUP(E32&"|"&H32&"", DB!$A:$N, 4, FALSE)), V32)) -> Hydrocortisone-Water Soluble | G32: =IF(OR(E32="", H32=""), "", IFERROR(VLOOKUP(E32&"|"&H32&"", DB!$A:$N, 5, FALSE), "")) | I32: 1018 | J32: =IF(OR(TRIM(E32)="", TRIM(H32)=""), "", IFERROR(IF(OR(VLOOKUP(E32&"|"&H32&"", DB!$A:$N, 6, FALSE)="", VLOOKUP(E32&"|"&H32&"", DB!$A:$N, 6, FALSE)="-"), "", VLOOKUP(E32&"|"&H32&"", DB!$A:$N, 6, FALSE)), "")) | K32: Ra1 | M32: 1 | N32: =IF(TRIM(D32)="", "", IF(N(L32)-N(M32)<=0, "X", N(L32)-N(M32))) -> X | V32: Hydrocortisone-Water Soluble
A33: 26-0045 | B33: 1/22 | C33: 박은영 | D33: =IF(OR(E33="", H33=""), V33, IFERROR(IF(VLOOKUP(E33&"|"&H33&"", DB!$A:$N, 4, FALSE)="", V33, VLOOKUP(E33&"|"&H33&"", DB!$A:$N, 4, FALSE)), V33)) -> Hydrocortisone-Water Soluble | G33: =IF(OR(E33="", H33=""), "", IFERROR(VLOOKUP(E33&"|"&H33&"", DB!$A:$N, 5, FALSE), "")) | J33: =IF(OR(TRIM(E33)="", TRIM(H33)=""), "", IFERROR(IF(OR(VLOOKUP(E33&"|"&H33&"", DB!$A:$N, 6, FALSE)="", VLOOKUP(E33&"|"&H33&"", DB!$A:$N, 6, FALSE)="-"), "", VLOOKUP(E33&"|"&H33&"", DB!$A:$N, 6, FALSE)), "")) | N33: =IF(TRIM(D33)="", "", IF(N(L33)-N(M33)<=0, "X", N(L33)-N(M33))) -> X | V33: Hydrocortisone-Water Soluble
C34: 최수민 | D34: =IF(OR(E34="", H34=""), V34, IFERROR(IF(VLOOKUP(E34&"|"&H34&"", DB!$A:$N, 4, FALSE)="", V34, VLOOKUP(E34&"|"&H34&"", DB!$A:$N, 4, FALSE)), V34)) -> ICG NHS Ester, 5 mg *1ea | F34: f | G34: =IF(OR(E34="", H34=""), "", IFERROR(VLOOKUP(E34&"|"&H34&"", DB!$A:$N, 5, FALSE), "")) | I34: 1001 | J34: =IF(OR(TRIM(E34)="", TRIM(H34)=""), "", IFERROR(IF(OR(VLOOKUP(E34&"|"&H34&"", DB!$A:$N, 6, FALSE)="", VLOOKUP(E34&"|"&H34&"", DB!$A:$N, 6, FALSE)="-"), "", VLOOKUP(E34&"|"&H34&"", DB!$A:$N, 6, FALSE)), "")) | K34: Fa1 | L34: 1 | N34: =IF(TRIM(D34)="", "", IF(N(L34)-N(M34)<=0, "X", N(L34)-N(M34))) -> 1 | V34: ICG NHS Ester, 5 mg *1ea
A35: 26-0078 | B35: 2/19 | C35: 최수민 | D35: =IF(OR(E35="", H35=""), V35, IFERROR(IF(VLOOKUP(E35&"|"&H35&"", DB!$A:$N, 4, FALSE)="", V35, VLOOKUP(E35&"|"&H35&"", DB!$A:$N, 4, FALSE)), V35)) -> ICG NHS Ester, 5 mg *1ea | F35: f | G35: =IF(OR(E35="", H35=""), "", IFERROR(VLOOKUP(E35&"|"&H35&"", DB!$A:$N, 5, FALSE), "")) | J35: =IF(OR(TRIM(E35)="", TRIM(H35)=""), "", IFERROR(IF(OR(VLOOKUP(E35&"|"&H35&"", DB!$A:$N, 6, FALSE)="", VLOOKUP(E35&"|"&H35&"", DB!$A:$N, 6, FALSE)="-"), "", VLOOKUP(E35&"|"&H35&"", DB!$A:$N, 6, FALSE)), "")) | L35: 1 | N35: =IF(TRIM(D35)="", "", IF(N(L35)-N(M35)<=0, "X", N(L35)-N(M35))) -> 1 | V35: ICG NHS Ester, 5 mg *1ea
A36: 26-0135 | B36: 3/26 | C36: 최희선 | D36: =IF(OR(E36="", H36=""), V36, IFERROR(IF(VLOOKUP(E36&"|"&H36&"", DB!$A:$N, 4, FALSE)="", V36, VLOOKUP(E36&"|"&H36&"", DB!$A:$N, 4, FALSE)), V36)) -> Isopropyl alcohol 1L *10ea | G36: =IF(OR(E36="", H36=""), "", IFERROR(VLOOKUP(E36&"|"&H36&"", DB!$A:$N, 5, FALSE), "")) | J36: =IF(OR(TRIM(E36)="", TRIM(H36)=""), "", IFERROR(IF(OR(VLOOKUP(E36&"|"&H36&"", DB!$A:$N, 6, FALSE)="", VLOOKUP(E36&"|"&H36&"", DB!$A:$N, 6, FALSE)="-"), "", VLOOKUP(E36&"|"&H36&"", DB!$A:$N, 6, FALSE)), "")) | N36: =IF(TRIM(D36)="", "", IF(N(L36)-N(M36)<=0, "X", N(L36)-N(M36))) -> X | V36: Isopropyl alcohol 1L *10ea
A37: 26-0014 | B37: 1/13 | C37: 초오 | D37: =IF(OR(E37="", H37=""), V37, IFERROR(IF(VLOOKUP(E37&"|"&H37&"", DB!$A:$N, 4, FALSE)="", V37, VLOOKUP(E37&"|"&H37&"", DB!$A:$N, 4, FALSE)), V37)) -> bb | E37: Aldrich | F37: 12g | G37: =IF(OR(E37="", H37=""), "", IFERROR(VLOOKUP(E37&"|"&H37&"", DB!$A:$N, 5, FALSE), "")) -> Search Failed | H37: 3we3 | I37: 1018 | J37: =IFERROR(IF(OR(VLOOKUP(E37&"|"&H37&"", DB!$A:$N, 6, FALSE)="", VLOOKUP(E37&"|"&H37&"", DB!$A:$N, 6, FALSE)="-"), "", VLOOKUP(E37&"|"&H37&"", DB!$A:$N, 6, FALSE)), "") | K37: Ca1 | L37: 3 | N37: =IF(TRIM(D37)="", "", IF(N(L37)-N(M37)<=0, "X", N(L37)-N(M37))) -> 3 | P37: =IF(OR(E37="", H37=""), "", IFERROR(IF(VLOOKUP(E37&"|"&H37&"", DB!$A:$N, 7, FALSE)="","-",VLOOKUP(E37&"|"&H37&"", DB!$A:$N, 7, FALSE)), "-")) -> - | Q37: =IF(OR(E37="", H37=""), "", IFERROR(IF(VLOOKUP(E37&"|"&H37&"", DB!$A:$N, 8, FALSE)="","-",VLOOKUP(E37&"|"&H37&"", DB!$A:$N, 8, FALSE)), "-")) -> - | R37: =IF(OR(E37="", H37=""), "", IFERROR(IF(VLOOKUP(E37&"|"&H37&"", DB!$A:$N, 9, FALSE)="","-",VLOOKUP(E37&"|"&H37&"", DB!$A:$N, 9, FALSE)), "-")) -> - | S37: =IF(OR(E37="", H37=""), "", IFERROR(IF(VLOOKUP(E37&"|"&H37&"", DB!$A:$N, 10, FALSE)="","-",VLOOKUP(E37&"|"&H37&"", DB!$A:$N, 10, FALSE)), "-")) -> - | T37: =IF(OR(E37="", H37=""), "", IFERROR(IF(VLOOKUP(E37&"|"&H37&"", DB!$A:$N, 11, FALSE)="","-",VLOOKUP(E37&"|"&H37&"", DB!$A:$N, 11, FALSE)), "-")) -> Product Not Found | U37: =IF(OR(E37="", H37=""), "", IFERROR(IF(VLOOKUP(E37&"|"&H37&"", DB!$A:$N, 12, FALSE)="","-",VLOOKUP(E37&"|"&H37&"", DB!$A:$N, 12, FALSE)), "-")) -> - | V37: ff
A38: 26-0469 | B38: 7/21 | C38: 윤벼리 | D38: =IF(OR(E38="", H38=""), V38, IFERROR(IF(VLOOKUP(E38&"|"&H38&"", DB!$A:$N, 4, FALSE)="", V38, VLOOKUP(E38&"|"&H38&"", DB!$A:$N, 4, FALSE)), V38)) -> Premixed TBS., 10X *2 | G38: =IF(OR(E38="", H38=""), "", IFERROR(VLOOKUP(E38&"|"&H38&"", DB!$A:$N, 5, FALSE), "")) | J38: =IF(OR(TRIM(E38)="", TRIM(H38)=""), "", IFERROR(IF(OR(VLOOKUP(E38&"|"&H38&"", DB!$A:$N, 6, FALSE)="", VLOOKUP(E38&"|"&H38&"", DB!$A:$N, 6, FALSE)="-"), "", VLOOKUP(E38&"|"&H38&"", DB!$A:$N, 6, FALSE)), "")) | N38: =IF(TRIM(D38)="", "", IF(N(L38)-N(M38)<=0, "X", N(L38)-N(M38))) -> X | V38: Premixed TBS., 10X *2
C39: 김영범 | D39: =IF(OR(E39="", H39=""), V39, IFERROR(IF(VLOOKUP(E39&"|"&H39&"", DB!$A:$N, 4, FALSE)="", V39, VLOOKUP(E39&"|"&H39&"", DB!$A:$N, 4, FALSE)), V39)) -> Serotonin hydrochloride 100mg | G39: =IF(OR(E39="", H39=""), "", IFERROR(VLOOKUP(E39&"|"&H39&"", DB!$A:$N, 5, FALSE), "")) | I39: 1001 | J39: =IF(OR(TRIM(E39)="", TRIM(H39)=""), "", IFERROR(IF(OR(VLOOKUP(E39&"|"&H39&"", DB!$A:$N, 6, FALSE)="", VLOOKUP(E39&"|"&H39&"", DB!$A:$N, 6, FALSE)="-"), "", VLOOKUP(E39&"|"&H39&"", DB!$A:$N, 6, FALSE)), "")) | K39: Da1 | N39: =IF(TRIM(D39)="", "", IF(N(L39)-N(M39)<=0, "X", N(L39)-N(M39))) -> X | V39: Serotonin hydrochloride 100mg
A40: 26-0102 | B40: 3/11 | C40: 김영범 | D40: =IF(OR(E40="", H40=""), V40, IFERROR(IF(VLOOKUP(E40&"|"&H40&"", DB!$A:$N, 4, FALSE)="", V40, VLOOKUP(E40&"|"&H40&"", DB!$A:$N, 4, FALSE)), V40)) -> Serotonin hydrochloride 100mg | G40: =IF(OR(E40="", H40=""), "", IFERROR(VLOOKUP(E40&"|"&H40&"", DB!$A:$N, 5, FALSE), "")) | J40: =IF(OR(TRIM(E40)="", TRIM(H40)=""), "", IFERROR(IF(OR(VLOOKUP(E40&"|"&H40&"", DB!$A:$N, 6, FALSE)="", VLOOKUP(E40&"|"&H40&"", DB!$A:$N, 6, FALSE)="-"), "", VLOOKUP(E40&"|"&H40&"", DB!$A:$N, 6, FALSE)), "")) | N40: =IF(TRIM(D40)="", "", IF(N(L40)-N(M40)<=0, "X", N(L40)-N(M40))) -> X | V40: Serotonin hydrochloride 100mg
...

Sheet index
A1: Room List | C1: Storage Temp. List | E1: Room | F1: Storage Temp. | G1: Cabinet
A2: 309 | C2: RT | E2: 1001 | F2: DF | G2: Da1 | H2: =IF(E2&F2="","",E2&"_"&F2) -> 1001_DF
A3: 1018 | C3: R | E3: 1001 | F3: F | G3: Fa1 | H3: =IF(E3&F3="","",E3&"_"&F3) -> 1001_F
A4: 1001 | C4: F | E4: 1001 | F4: R | G4: Ra1 | H4: =IF(E4&F4="","",E4&"_"&F4) -> 1001_R
C5: DF | E5: 1001 | F5: RT | G5: Ca2 | H5: =IF(E5&F5="","",E5&"_"&F5) -> 1001_RT
E6: 1018 | F6: DF | G6: Da1 | H6: =IF(E6&F6="","",E6&"_"&F6) -> 1018_DF
E7: 1018 | F7: DF | G7: Db1 | H7: =IF(E7&F7="","",E7&"_"&F7) -> 1018_DF
E8: 1018 | F8: DF | G8: Db2 | H8: =IF(E8&F8="","",E8&"_"&F8) -> 1018_DF
E9: 1018 | F9: F | G9: Fa1 | H9: =IF(E9&F9="","",E9&"_"&F9) -> 1018_F
E10: 1018 | F10: R | G10: Ra1 | H10: =IF(E10&F10="","",E10&"_"&F10) -> 1018_R
E11: 1018 | F11: RT | G11: Ca1 | H11: =IF(E11&F11="","",E11&"_"&F11) -> 1018_RT
E12: 1018 | F12: RT | G12: Ca2 | H12: =IF(E12&F12="","",E12&"_"&F12) -> 1018_RT
E13: 1018 | F13: RT | G13: Sa1 | H13: =IF(E13&F13="","",E13&"_"&F13) -> 1018_RT
E14: 309 | F14: DF | G14: Da1 | H14: =IF(E14&F14="","",E14&"_"&F14) -> 309_DF
E15: 309 | F15: F | G15: Fb1 | H15: =IF(E15&F15="","",E15&"_"&F15) -> 309_F
E16: 309 | F16: R | G16: Ra1 | H16: =IF(E16&F16="","",E16&"_"&F16) -> 309_R
E17: 309 | F17: RT | G17: Ca1 | H17: =IF(E17&F17="","",E17&"_"&F17) -> 309_RT
... E19: 309 | F19: RT | G19: Sa1 | H19: =IF(E19&F19="","",E19&"_"&F19) -> 309_RT
H20: =IF(E20&F20="","",E20&"_"&F20)
H21: =IF(E21&F21="","",E21&"_"&F21)
H22: =IF(E22&F22="","",E22&"_"&F22)
H23: =IF(E23&F23="","",E23&"_"&F23)
H24: =IF(E24&F24="","",E24&"_"&F24)
H25: =IF(E25&F25="","",E25&"_"&F25)
H26: =IF(E26&F26="","",E26&"_"&F26)
H27: =IF(E27&F27="","",E27&"_"&F27)
H28: =IF(E28&F28="","",E28&"_"&F28)
H29: =IF(E29&F29="","",E29&"_"&F29)
H30: =IF(E30&F30="","",E30&"_"&F30)
H31: =IF(E31&F31="","",E31&"_"&F31)
... H49: =IF(E49&F49="","",E49&"_"&F49)

Sheet DB
A1: Key | B1: Manufacturer | C1: Catalog No. | D1: Product Name | E1: CAS No. | F1: Storage Temp. | G1: Sensitivity | H1: Signal Word | I1: Key Hazards | J1: Detailed Hazard Classification | K1: Detail_Link | L1: SDS_Link | M1: SDS_Local_Path | N1: Revision Date
A2: =B2&"|"&C2 -> 1|1 | B2: 1 | C2: 1 | D2: [ab76003] Anti-MMP9 antibody [EP1254] | E2: Manual Input Required | F2: - | G2: - | H2: - | I2: - | J2: - | K2: - | L2: - | M2: - | N2: 2026-08-11
A3: =B3&"|"&C3 -> Aa|1 | B3: Aa | C3: 1 | D3: [ab76003] Anti-MMP9 antibody [EP1254] | E3: Manual Input Required | F3: - | G3: - | H3: - | I3: - | J3: - | K3: - | L3: - | M3: - | N3: 2026-08-11
A4: =B4&"|"&C4 -> Aldrich|440140 | B4: Aldrich | C4: 440140 | D4: (3-Aminopropyl)triethoxysilane | E4: 919-30-2 | F4: - | G4: - | H4: ● Danger | I4: ▲ Corrosive / Eye Damage | J4: H314: Causes severe skin burns and eye damage / H317: May cause an allergic skin reaction / H302: Harmful if swallowed | K4: https://www.sigmaaldrich.com/KR/en/product/aldrich/440140 | L4: https://www.sigmaaldrich.com/KR/ko/sds/aldrich/440140 | M4: C:\Users\Jeonghun Lee\.gemini\antigravity\scratch\chemical manager\sds\(3-Aminopropyl)triethoxysilane (Aldrich, 440140).pdf | N4: 46246
A5: =B5&"|"&C5 -> Aldrich|131377 | B5: Aldrich | C5: 131377 | D5: 1,10-Phenanthroline | E5: 66-71-7 | F5: - | G5: - | H5: - | I5: ● Toxic, ■ Environmental Hazard | J5: H410: Very toxic to aquatic life with long lasting effects / H301: Toxic if swallowed | K5: https://www.sigmaaldrich.com/KR/en/product/aldrich/131377 | L5: https://www.sigmaaldrich.com/KR/ko/sds/aldrich/131377 | M5: C:\Users\Jeonghun Lee\.gemini\antigravity\scratch\chemical manager\sds\1,10-Phenanthroline (Aldrich, 131377).pdf | N5: 46247
A6: =B6&"|"&C6 -> Aldrich|659452 | B6: Aldrich | C6: 659452 | D6: 1-Adamantanethiol | E6: 34301-54-7 | F6: RT | G6: - | H6: ▲ Warning | I6: ● Toxic, ◆ Irritant / Sensitizer | J6: H319: Causes serious eye irritation / H301: Toxic if swallowed | K6: https://www.sigmaaldrich.com/KR/en/product/aldrich/659452 | L6: https://www.sigmaaldrich.com/KR/ko/sds/aldrich/659452 | M6: C:\Users\Jeonghun Lee\.gemini\antigravity\scratch\chemical manager\sds\1-Adamantanethiol (Aldrich, 659452).pdf | N6: 46247
A7: =B7&"|"&C7 -> Aldrich|402788 | B7: Aldrich | C7: 402788 | D7: Acetaldehyde | E7: 75-07-0 | F7: R | G7: - | H7: ▲ Warning | I7: ★ Flammable, ◆ Irritant / Sensitizer, ▼ Health Hazard | J7: H319: Causes serious eye irritation / H335: May cause respiratory irritation / H341: Suspected of causing genetic defects / H350: May cause cancer / H224: Extremely flammable liquid and vapor | K7: https://www.sigmaaldrich.com/KR/en/product/sial/402788 | L7: https://www.sigmaaldrich.com/KR/ko/sds/sial/402788 | M7: C:\Users\Jeonghun Lee\.gemini\antigravity\scratch\chemical manager\sds\Acetaldehyde (Aldrich, 402788).pdf | N7: 2026-08-11
A8: =B8&"|"&C8 -> Aldrich|909270-10G | B8: Aldrich | C8: 909270-10G | D8: Acrylic anhydride | E8: 2051-76-5 | F8: R | G8: - | H8: ▲ Warning | I8: ◆ Irritant / Sensitizer | J8: H315: Causes skin irritation / H317: May cause an allergic skin reaction / H319: Causes serious eye irritation / H335: May cause respiratory irritation / H302: Harmful if swallowed | K8: https://www.sigmaaldrich.com/KR/en/product/aldrich/909270 | L8: https://www.sigmaaldrich.com/KR/ko/sds/aldrich/909270 | M8: C:\Users\Jeonghun Lee\.gemini\antigravity\scratch\chemical manager\sds\Acrylic anhydride (Aldrich, 909270).pdf | N8: 2026-08-11
A9: =B9&"|"&C9 -> Aldrich|803200 | B9: Aldrich | C9: 803200 | D9: DTSSP (3,3′-dithiobis(sulfosuccinimidyl propionate)) | E9: 81069-02-5 | F9: R | G9: - | H9: - | I9: - | J9: - | K9: https://www.sigmaaldrich.com/KR/en/product/aldrich/803200 | L9: https://www.sigmaaldrich.com/KR/ko/sds/aldrich/803200 | M9: C:\Users\Jeonghun Lee\.gemini\antigravity\scratch\chemical manager\sds\DTSSP (3,3′-dithiobis(sulfosuccinimidyl propionate)) (Aldrich, 803200).pdf | N9: 2026-08-11
A10: =B10&"|"&C10 -> Aldrich|359238 | B10: Aldrich | C10: 359238 | D10: Perfluorooctane | E10: 307-34-6 | F10: RT | G10: - | H10: - | I10: - | J10: - | K10: https://www.sigmaaldrich.com/KR/en/product/aldrich/359238 | L10: https://www.sigmaaldrich.com/KR/ko/sds/aldrich/359238 | M10: C:\Users\Jeonghun Lee\.gemini\antigravity\scratch\chemical manager\sds\Perfluorooctane (Aldrich, 359238).pdf | N10: 2026-08-12
A11: =B11&"|"&C11 -> Aldrich|8.02361 | B11: Aldrich | C11: 8.02361 | D11: p-Chloranil | E11: 118-75-2 | F11: RT | G11: - | H11: ▲ Warning | I11: ● Toxic, ▲ Corrosive / Eye Damage, ◆ Irritant / Sensitizer, ■ Environmental Hazard | J11: H317: May cause an allergic skin reaction / H318: Causes serious eye damage / H410: Very toxic to aquatic life with long lasting effects / H315: Causes skin irritation | K11: https://www.sigmaaldrich.com/KR/en/product/mm/802361 | L11: https://www.sigmaaldrich.com/KR/ko/sds/mm/8.02361 | M11: C:\Users\Jeonghun Lee\.gemini\antigravity\scratch\chemical manager\sds\p-Chloranil (Aldrich, 8.02361).pdf | N11: 46247
A12: =B12&"|"&C12 -> Fff|2w5w | B12: Fff | C12: 2w5w | D12: [B7651] Brefeldin A | E12: Manual Input Required | F12: - | G12: - | H12: - | I12: - | J12: - | K12: - | L12: - | M12: - | N12: 2026-08-11
A13: =B13&"|"&C13 -> TCI|c0119 | B13: TCI | C13: c0119 | D13: 1,1'-Carbonyldiimidazole | E13: 530-62-1 | F13: RT | G13: Moisture, Heat | H13: ● Danger | I13: ▲ Corrosive / Eye Damage | J13: H302 : Harmful if swallowed. H314 : Causes severe skin burns and eye damage. | K13: https://www.tcichemicals.com/KR/en/p/c0119 | L13: https://www.tcichemicals.com/KR/en/documentSearch | M13: C:\Users\Jeonghun Lee\.gemini\antigravity\scratch\chemical manager\sds\1,1'-Carbonyldiimidazole (TCI, c0119).pdf | N13: 46246
A14: =B14&"|"&C14 -> TCI|B2065 | B14: TCI | C14: B2065 | D14: 3-Bromopropionyl Chloride | E14: 15486-96-1 | F14: RT | G14: Moisture Sensitive, Heat Sensitive | H14: ● Danger | I14: ▲ Corrosive / Eye Damage | J14: H314 : Causes severe skin burns and eye damage. H227 : Combustible liquid. H290 : May be corrosive to metals. | K14: https://www.tcichemicals.com/KR/en/p/B2065 | L14: https://www.tcichemicals.com/KR/en/documentSearch | M14: C:\Users\Jeonghun Lee\.gemini\antigravity\scratch\chemical manager\sds\3-Bromopropionyl Chloride (TCI, B2065).pdf | N14: 2026-08-12
A15: =B15&"|"&C15 -> TCI|b4263 | B15: TCI | C15: b4263 | D15: Bis(2-hydroxyethyl) Disulfide | E15: 1892-29-1 | F15: RT | G15: Air | H15: ● Danger | I15: ● Toxic, ◆ Irritant / Sensitizer | J15: H301 : Toxic if swallowed. H315 : Causes skin irritation. H319 : Causes serious eye irritation. | K15: https://www.tcichemicals.com/KR/en/p/b4263 | L15: https://www.tcichemicals.com/KR/en/documentSearch | M15: C:\Users\Jeonghun Lee\.gemini\antigravity\scratch\chemical manager\sds\Bis(2-hydroxyethyl) Disulfide (TCI, b4263).pdf | N15: 46246
A16: =B16&"|"&C16 -> ThermoFisher|704060F | B16: ThermoFisher | C16: 704060F | D16: Alexa Fluor 488 Recombinant F(ab)-Rabbit Monoclonal Antibody (15H9L93) | F16: RT | G16: - | H16: - | I16: - | J16: - | K16: https://www.thermofisher.com/order/catalog/product/704060F | L16: https://www.thermofisher.com/search/browse/results?term=704060F | M16: - | N16: 2026-08-12
A17: =B17&"|"&C17 -> ThermoFisher|A10436 | B17: ThermoFisher | C17: A10436 | D17: Alexa Fluor™ 488 Hydrazide | F17: RT | G17: - | H17: - | I17: - | J17: - | K17: https://www.thermofisher.com/order/catalog/product/A10436 | L17: https://documents.thermofisher.com/TFS-Assets/LSG/SDS/A10436_MTR-NALT_EN.pdf | M17: C:\Users\Jeonghun Lee\.gemini\antigravity\scratch\chemical manager\sds\Alexa Fluor™ 488 Hydrazide (ThermoFisher, A10436).pdf | N17: 2026-08-12
A18: =B18&"|"&C18 -> Aldrich|3we3 | B18: Aldrich | C18: 3we3 | D18: bb | E18: Search Failed | F18: - | G18: - | H18: - | I18: - | J18: - | K18: Product Not Found | L18: - | M18: - | N18: -
A19: =B19&"|"&C19 -> Abcam|ab92536 | B19: Abcam | C19: ab92536 | D19: Anti-MMP2 antibody [EPR1184] - recombinant (ab92536) | E19: N/A | F19: F | G19: - | H19: - | I19: - | J19: - | K19: https://www.abcam.com/en-us/products/primary-antibodies/mmp2-antibody-epr1184-ab92536 | L19: - | M19: - | N19: 46247.625

Sheet Guide
A1: 📖 연구실 시약 및 주문 대장 엑셀 작성·사용 가이드 (일반 사용자용)
A4: 📝 1. Orderbook (주문 대장) 작성 방법 및 주의사항
A5: 연구실에서 새로운 시약을 구매/신청할 때 작성하는 주문 대장 입력 수칙입니다.
A7: 📌 Orderbook 주요 항목 기입 규칙
A8: No. | B8: 항목명 | C8: 기입 규칙 및 세부 설명 | D8: 추천 표기법 및 예시
A9: 1 | B9: 번호 (주문 번호) | C9: 고유한 주문 식별 번호를 기입합니다. | D9: 26-0001, 26-0063
A10: 2 | B10: 날짜 | C10: 주문 일자를 YYYY-MM-DD 형식으로 정확히 기입합니다. | D10: 46247
A11: 3 | B11: 주문자 | C11: 신청 연구원의 이름을 기입합니다. | D11: 홍길동
A12: 4 | B12: 회사 (제조사) | C12: 공식 제조사 영문명을 정확히 입력합니다. | D12: Thermo Fisher, Sigma-Aldrich, TCI, Abcam
A13: 5 | B13: 품목명 (시약명) | C13: 시약의 정확한 영문/국문 시약명을 기입합니다. | D13: Acetone, Sodium Chloride
A14: 6 | B14: 품번 (Catalog No.) | C14: 제조사 공식 카탈로그 번호 (앞자리 0/하이픈 누락 주의) | D14: 659452, 131377
A15: 7 | B15: 용량 (Package Size) | C15: 포장 용량을 단위와 함께 입력합니다. | D15: 500 mL, 25 g, 1 L
A16: 8 | B16: 수량 (Quantity) | C16: 주문한 수량을 숫자로 입력합니다. | D16: 1, 2, 5
A17: 9 | B17: 수령확인 (Status) | C17: 시약 수령 완료 시 'O' 또는 'ㅇ'을 기입합니다. (미입력 시 현황판 제외) | D17: O
A19: ⚠️ Orderbook 작성 시 절대 금지 및 주의사항
A20: ❌ 중간 빈 줄(Blank Row) 금지: 데이터 행 사이에 완전히 비어 있는 줄을 남겨두지 마세요. 프로그램이 데이터 읽기를 중간에 중단할 수 있습니다.
A21: ❌ 제조사 및 품번 오탈자 주의: 제조사 이름이나 카탈로그 번호에 띄어쓰기/오탈자가 있으면 홈페이지 크롤링 검색에 실패할 수 있습니다.
A24: 🧪 2. ChemicalList.xlsx (시약 현황 관리판) 사용 가이드
A25: 📌 시트 구성 및 역할 설명
A26: 시트명 | B26: 구분 | C26: 역할 및 설명 | D26: 비고
A27: ChemicalList | B27: 메인 현황판 | C27: 연구원이 직접 보관장소, 캐비넷, 사용수량 등을 기입하고 확인하는 화면 | D27: 연구원 직접 입력
A28: index | B28: 보관장소 색인 | C28: 연구실 보관장소(Room), 보관온도(Storage Temp.), 캐비넷(Cabinet) 유효 리스트 정의 | D28: 표준 범위 정의 시트
A29: DB | B29: 마스터 DB | C29: 크롤링 및 수집된 화학물질의 위험성, CAS No., 보관온도, SDS 링크 저장 | D29: 자동 관리 (직접 수정 주의)
A30: Guide | B30: 사용 가이드 | C30: 연구실 구성원이 엑셀 및 자동 동기화 프로그램을 사용할 때 참고하는 수칙 | D30: 안내 전용 시트
A32: ✍️ 연구원이 ChemicalList 시트에서 직접 기입/수정하는 항목
A33: 항목명 | B33: 필드 구분 | C33: 입력 수칙 및 방법 | D33: 입력 예시
A34: Room (보관 장소) | B34: 입력 항목 | C34: 시약이 비치된 연구실 방 번호를 기입합니다. | D34: 501호, 502호
A35: Cabinet (캐비넷) | B35: 입력 항목 | C35: Room 및 보관온도 조건에 맞춘 시약장 번호를 입력합니다. | D35: A-1, B-2
A36: Used (사용 수량) | B36: 입력 항목 | C36: 시약을 사용했을 때 사용 수량을 업데이트합니다. (Quantity와 비교하여 Status 자동 결정) | D36: 1, 2
A37: Remarks (비고) | B37: 입력 항목 | C37: 개봉일자, 특이사항, 사용자 메모 등을 자유롭게 기입합니다. | D37: 2026-08-10 개봉
A39: ⚠️ ChemicalList.xlsx 작성 시 절대 주의사항
A40: ❌ 수식 셀 (VLOOKUP) 직접 삭제/수정 금지: Storage Temp., CAS No., Sensitivity, Signal Word 등은 DB 시트와 =IFERROR(VLOOKUP(...)) 수식으로 자동 연동되어 있습니다. 보관온도 변경 시 DB 시트에서 해당 시약의 보관온도를 수정하세요.
A41: ❌ DB 시트 행 삭제 금지: DB 시트의 행을 삭제하면 ChemicalList 시트 수식에 #REF! 오류가 발생합니다.
A42: 💡 자가 합성 시약 / 소분 시약 기입 규칙: 제조사나 카탈로그 번호가 없는 자체 합성 시약은 제조사와 품번을 비워두고 시약명과 위치 정보만 기입하면 기존 텍스트가 100% 그대로 안전하게 유지됩니다.
A45: 🔄 3. 프로그램 자동 동기화 및 문의처
A46: 1. 안전한 열람/작업 | B46: ChemicalList.xlsx 파일이 연구원 컴퓨터에서 켜져 있어도 프로그램이 자동 임시 백업 및 안전 동기화를 진행하므로 파일 손실 없이 안심하고 작업하실 수 있습니다.
A47: 2. 백업 파일 자동 생성 | B47: 동기화 진행 시마다 backup/ 폴더에 ChemicalList_backup_YYYYMMDD_HHMMSS.xlsx 형태로 자동 백업됩니다.
A48: 3. 제작자 및 문의처 | B48: 제작자: Jeonghun Lee (문의 이메일: jhl22@hanyang.ac.kr)
