Workbook

Sheet ChemicalList
A1: Order No. | B1: Order Date | C1: Ordered By | D1: Product Name | E1: Manufacturer | F1: Package Size | G1: CAS No. | H1: Catalog No. | I1: Room | J1: Storage Temp. | K1: Cabinet | L1: Quantity | M1: Used | N1: Status | O1: Remarks | P1: Sensitivity | Q1: Signal Word | R1: Key Hazards | S1: Detailed Hazard Classification | T1: Detail_Link | U1: SDS_Link
D2: (2-Hydroxypropyl)-ß-cyclodextrin, powder | E2: Aldrich | F2: 100 g | G2: 128446-35-5 | H2: 359238 | I2: 309 | J2: R | K2: Ra1 | L2: 1 | N2: =IF(TRIM(D2)="", "", IF(N(L2)-N(M2)<=0, "X", N(L2)-N(M2))) -> 1 | P2: =_xlfn.IFNA(VLOOKUP($H2,DB!$B:$M,5,FALSE),"") -> 0 | Q2: =_xlfn.IFNA(VLOOKUP($H2,DB!$B:$M,6,FALSE),"") -> 0 | R2: =_xlfn.IFNA(VLOOKUP($H2,DB!$B:$M,7,FALSE),"") -> 0 | S2: =_xlfn.IFNA(VLOOKUP($H2,DB!$B:$M,8,FALSE),"") -> 0 | T2: =_xlfn.IFNA(VLOOKUP($H2,DB!$B:$M,9,FALSE),"") -> https://www.sigmaaldrich.com/KR/en/product/aldrich/359238 | U2: =_xlfn.IFNA(VLOOKUP($H2,DB!$B:$M,10,FALSE),"") -> 정보 없음
D3: (3-Aminopropyl)triethoxysilane | E3: Aldrich | F3: 100 mL | G3: 919-30-2 | H3: 440140 | I3: 1018 | J3: F | K3: Fa1 | L3: 1 | N3: =IF(TRIM(D3)="", "", IF(N(L3)-N(M3)<=0, "X", N(L3)-N(M3))) -> 1 | P3: =_xlfn.IFNA(VLOOKUP($H3,DB!$B:$M,5,FALSE),"") -> N/A | Q3: =_xlfn.IFNA(VLOOKUP($H3,DB!$B:$M,6,FALSE),"") -> ● 위험 | R3: =_xlfn.IFNA(VLOOKUP($H3,DB!$B:$M,7,FALSE),"") -> ▲ 부식성/눈손상 | S3: =_xlfn.IFNA(VLOOKUP($H3,DB!$B:$M,8,FALSE),"") -> H302: Harmful if swallowed / H314: Causes severe skin burns and eye damage / H317: May cause an allergic skin reaction | T3: =_xlfn.IFNA(VLOOKUP($H3,DB!$B:$M,9,FALSE),"") -> https://www.sigmaaldrich.com/KR/ko/product/aldrich/440140 | U3: =_xlfn.IFNA(VLOOKUP($H3,DB!$B:$M,10,FALSE),"") -> https://www.sigmaaldrich.com/KR/ko/sds/aldrich/440140
A4: 26-0043 | B4: 1/28 | C4: 초오 | D4: [ab213480] Anti-PD-L1 antibody | I4: 1018 | K4: Ca1 | M4: 1 | N4: =IF(TRIM(D4)="", "", IF(N(L4)-N(M4)<=0, "X", N(L4)-N(M4))) -> X | P4: =_xlfn.IFNA(VLOOKUP($H4,DB!$B:$M,5,FALSE),"") | Q4: =_xlfn.IFNA(VLOOKUP($H4,DB!$B:$M,6,FALSE),"") | R4: =_xlfn.IFNA(VLOOKUP($H4,DB!$B:$M,7,FALSE),"") | S4: =_xlfn.IFNA(VLOOKUP($H4,DB!$B:$M,8,FALSE),"") | T4: =_xlfn.IFNA(VLOOKUP($H4,DB!$B:$M,9,FALSE),"") | U4: =_xlfn.IFNA(VLOOKUP($H4,DB!$B:$M,10,FALSE),"")
C5: 윤벼리 | D5: [ab76003] Anti-MMP9 antibody [EP1254] | E5: 1 | F5: 1 | G5: afd | H5: 1 | I5: 1001 | J5: RT | K5: Ca2 | L5: 2 | N5: =IF(TRIM(D5)="", "", IF(N(L5)-N(M5)<=0, "X", N(L5)-N(M5))) -> 2 | P5: =_xlfn.IFNA(VLOOKUP($H5,DB!$B:$M,5,FALSE),"") -> 0 | Q5: =_xlfn.IFNA(VLOOKUP($H5,DB!$B:$M,6,FALSE),"") -> 0 | R5: =_xlfn.IFNA(VLOOKUP($H5,DB!$B:$M,7,FALSE),"") -> 0 | S5: =_xlfn.IFNA(VLOOKUP($H5,DB!$B:$M,8,FALSE),"") -> 0 | T5: =_xlfn.IFNA(VLOOKUP($H5,DB!$B:$M,9,FALSE),"") -> 사용자 직접 입력 요망 | U5: =_xlfn.IFNA(VLOOKUP($H5,DB!$B:$M,10,FALSE),"") -> 0
A6: 26-0057 | B6: 2/4 | C6: 윤벼리 | D6: [ab76003] Anti-MMP9 antibody [EP1254] | E6: 1 | F6: 1 | G6: afd | H6: 1 | J6: RT | L6: 2 | N6: =IF(TRIM(D6)="", "", IF(N(L6)-N(M6)<=0, "X", N(L6)-N(M6))) -> 2 | P6: =_xlfn.IFNA(VLOOKUP($H6,DB!$B:$M,5,FALSE),"") -> 0 | Q6: =_xlfn.IFNA(VLOOKUP($H6,DB!$B:$M,6,FALSE),"") -> 0 | R6: =_xlfn.IFNA(VLOOKUP($H6,DB!$B:$M,7,FALSE),"") -> 0 | S6: =_xlfn.IFNA(VLOOKUP($H6,DB!$B:$M,8,FALSE),"") -> 0 | T6: =_xlfn.IFNA(VLOOKUP($H6,DB!$B:$M,9,FALSE),"") -> 사용자 직접 입력 요망 | U6: =_xlfn.IFNA(VLOOKUP($H6,DB!$B:$M,10,FALSE),"") -> 0
C7: 초오 | D7: [B7651] Brefeldin A | E7: Fff | F7: a | G7: 35w5 | H7: 2w5w | I7: 1018 | J7: DF | K7: Db2 | L7: 2 | M7: 1 | N7: =IF(TRIM(D7)="", "", IF(N(L7)-N(M7)<=0, "X", N(L7)-N(M7))) -> 1 | P7: =_xlfn.IFNA(VLOOKUP($H7,DB!$B:$M,5,FALSE),"") -> 0 | Q7: =_xlfn.IFNA(VLOOKUP($H7,DB!$B:$M,6,FALSE),"") -> 0 | R7: =_xlfn.IFNA(VLOOKUP($H7,DB!$B:$M,7,FALSE),"") -> 0 | S7: =_xlfn.IFNA(VLOOKUP($H7,DB!$B:$M,8,FALSE),"") -> 0 | T7: =_xlfn.IFNA(VLOOKUP($H7,DB!$B:$M,9,FALSE),"") -> 사용자 직접 입력 요망 | U7: =_xlfn.IFNA(VLOOKUP($H7,DB!$B:$M,10,FALSE),"") -> 0
A8: 26-0040 | B8: 1/26 | C8: 초오 | D8: [B7651] Brefeldin A | E8: Fff | F8: a | G8: 35w5 | H8: 2w5w | J8: DF | L8: 2 | N8: =IF(TRIM(D8)="", "", IF(N(L8)-N(M8)<=0, "X", N(L8)-N(M8))) -> 2 | P8: =_xlfn.IFNA(VLOOKUP($H8,DB!$B:$M,5,FALSE),"") -> 0 | Q8: =_xlfn.IFNA(VLOOKUP($H8,DB!$B:$M,6,FALSE),"") -> 0 | R8: =_xlfn.IFNA(VLOOKUP($H8,DB!$B:$M,7,FALSE),"") -> 0 | S8: =_xlfn.IFNA(VLOOKUP($H8,DB!$B:$M,8,FALSE),"") -> 0 | T8: =_xlfn.IFNA(VLOOKUP($H8,DB!$B:$M,9,FALSE),"") -> 사용자 직접 입력 요망 | U8: =_xlfn.IFNA(VLOOKUP($H8,DB!$B:$M,10,FALSE),"") -> 0
A9: 26-0038 | B9: 1/26 | C9: 초오 | D9: [I0634] Ionomycin calcium salt | E9: Fff | F9: a | G9: 35w5 | H9: 2w5w | I9: 1018 | J9: RT | K9: Ca2 | L9: 2 | N9: =IF(TRIM(D9)="", "", IF(N(L9)-N(M9)<=0, "X", N(L9)-N(M9))) -> 2 | P9: =_xlfn.IFNA(VLOOKUP($H9,DB!$B:$M,5,FALSE),"") -> 0 | Q9: =_xlfn.IFNA(VLOOKUP($H9,DB!$B:$M,6,FALSE),"") -> 0 | R9: =_xlfn.IFNA(VLOOKUP($H9,DB!$B:$M,7,FALSE),"") -> 0 | S9: =_xlfn.IFNA(VLOOKUP($H9,DB!$B:$M,8,FALSE),"") -> 0 | T9: =_xlfn.IFNA(VLOOKUP($H9,DB!$B:$M,9,FALSE),"") -> 사용자 직접 입력 요망 | U9: =_xlfn.IFNA(VLOOKUP($H9,DB!$B:$M,10,FALSE),"") -> 0
C10: 초오 | D10: [S0809.5000] Sucrose | I10: 1001 | J10: RT | K10: Da1 | N10: =IF(TRIM(D10)="", "", IF(N(L10)-N(M10)<=0, "X", N(L10)-N(M10))) -> X | P10: =_xlfn.IFNA(VLOOKUP($H10,DB!$B:$M,5,FALSE),"") | Q10: =_xlfn.IFNA(VLOOKUP($H10,DB!$B:$M,6,FALSE),"") | R10: =_xlfn.IFNA(VLOOKUP($H10,DB!$B:$M,7,FALSE),"") | S10: =_xlfn.IFNA(VLOOKUP($H10,DB!$B:$M,8,FALSE),"") | T10: =_xlfn.IFNA(VLOOKUP($H10,DB!$B:$M,9,FALSE),"") | U10: =_xlfn.IFNA(VLOOKUP($H10,DB!$B:$M,10,FALSE),"")
A11: 26-0049 | B11: 1/29 | C11: 초오 | D11: [S0809.5000] Sucrose | N11: =IF(TRIM(D11)="", "", IF(N(L11)-N(M11)<=0, "X", N(L11)-N(M11))) -> X | P11: =_xlfn.IFNA(VLOOKUP($H11,DB!$B:$M,5,FALSE),"") | Q11: =_xlfn.IFNA(VLOOKUP($H11,DB!$B:$M,6,FALSE),"") | R11: =_xlfn.IFNA(VLOOKUP($H11,DB!$B:$M,7,FALSE),"") | S11: =_xlfn.IFNA(VLOOKUP($H11,DB!$B:$M,8,FALSE),"") | T11: =_xlfn.IFNA(VLOOKUP($H11,DB!$B:$M,9,FALSE),"") | U11: =_xlfn.IFNA(VLOOKUP($H11,DB!$B:$M,10,FALSE),"")
D12: 0.1 M Disodium hydrogenphos | I12: 309 | J12: DF | K12: Da1 | L12: 1 | N12: =IF(TRIM(D12)="", "", IF(N(L12)-N(M12)<=0, "X", N(L12)-N(M12))) -> 1 | P12: =_xlfn.IFNA(VLOOKUP($H12,DB!$B:$M,5,FALSE),"") | Q12: =_xlfn.IFNA(VLOOKUP($H12,DB!$B:$M,6,FALSE),"") | R12: =_xlfn.IFNA(VLOOKUP($H12,DB!$B:$M,7,FALSE),"") | S12: =_xlfn.IFNA(VLOOKUP($H12,DB!$B:$M,8,FALSE),"") | T12: =_xlfn.IFNA(VLOOKUP($H12,DB!$B:$M,9,FALSE),"") | U12: =_xlfn.IFNA(VLOOKUP($H12,DB!$B:$M,10,FALSE),"")
D13: 0.1 M Sodium phosphate | E13: Made By Nki | I13: 1018 | J13: R | K13: Ra1 | L13: 1 | N13: =IF(TRIM(D13)="", "", IF(N(L13)-N(M13)<=0, "X", N(L13)-N(M13))) -> 1 | P13: =_xlfn.IFNA(VLOOKUP($H13,DB!$B:$M,5,FALSE),"") | Q13: =_xlfn.IFNA(VLOOKUP($H13,DB!$B:$M,6,FALSE),"") | R13: =_xlfn.IFNA(VLOOKUP($H13,DB!$B:$M,7,FALSE),"") | S13: =_xlfn.IFNA(VLOOKUP($H13,DB!$B:$M,8,FALSE),"") | T13: =_xlfn.IFNA(VLOOKUP($H13,DB!$B:$M,9,FALSE),"") | U13: =_xlfn.IFNA(VLOOKUP($H13,DB!$B:$M,10,FALSE),"")
D14: 1,1,1,2,3,4,4,5,5,5-Decafluoropentane | E14: Aldrich | F14: 100 mL | G14: 38495-42-8 | H14: 94884 | I14: 309 | J14: DF | K14: Da1 | L14: 1 | N14: =IF(TRIM(D14)="", "", IF(N(L14)-N(M14)<=0, "X", N(L14)-N(M14))) -> 1 | P14: =_xlfn.IFNA(VLOOKUP($H14,DB!$B:$M,5,FALSE),"") -> 0 | Q14: =_xlfn.IFNA(VLOOKUP($H14,DB!$B:$M,6,FALSE),"") -> 0 | R14: =_xlfn.IFNA(VLOOKUP($H14,DB!$B:$M,7,FALSE),"") -> 0 | S14: =_xlfn.IFNA(VLOOKUP($H14,DB!$B:$M,8,FALSE),"") -> 0 | T14: =_xlfn.IFNA(VLOOKUP($H14,DB!$B:$M,9,FALSE),"") -> 정보 없음 | U14: =_xlfn.IFNA(VLOOKUP($H14,DB!$B:$M,10,FALSE),"") -> 정보 없음
D15: 1,10-Phenanthroline | E15: Aldrich | F15: 5 g | G15: 66-71-7 | H15: 131377 | I15: 1018 | J15: DF | K15: Db2 | L15: 1 | N15: =IF(TRIM(D15)="", "", IF(N(L15)-N(M15)<=0, "X", N(L15)-N(M15))) -> 1 | P15: =_xlfn.IFNA(VLOOKUP($H15,DB!$B:$M,5,FALSE),"") -> 0 | Q15: =_xlfn.IFNA(VLOOKUP($H15,DB!$B:$M,6,FALSE),"") -> 정보 없음 | R15: =_xlfn.IFNA(VLOOKUP($H15,DB!$B:$M,7,FALSE),"") -> ● 독성, ■ 환경유해 | S15: =_xlfn.IFNA(VLOOKUP($H15,DB!$B:$M,8,FALSE),"") -> H301: Toxic if swallowed / H410: Very toxic to aquatic life with long lasting effects | T15: =_xlfn.IFNA(VLOOKUP($H15,DB!$B:$M,9,FALSE),"") -> https://www.sigmaaldrich.com/KR/ko/product/aldrich/131377 | U15: =_xlfn.IFNA(VLOOKUP($H15,DB!$B:$M,10,FALSE),"") -> https://www.sigmaaldrich.com/KR/ko/sds/aldrich/131377
A16: 26-0465 | B16: 7/20 | C16: 윤벼리 | D16: Acrylamide | N16: =IF(TRIM(D16)="", "", IF(N(L16)-N(M16)<=0, "X", N(L16)-N(M16))) -> X | P16: =_xlfn.IFNA(VLOOKUP($H16,DB!$B:$M,5,FALSE),"") | Q16: =_xlfn.IFNA(VLOOKUP($H16,DB!$B:$M,6,FALSE),"") | R16: =_xlfn.IFNA(VLOOKUP($H16,DB!$B:$M,7,FALSE),"") | S16: =_xlfn.IFNA(VLOOKUP($H16,DB!$B:$M,8,FALSE),"") | T16: =_xlfn.IFNA(VLOOKUP($H16,DB!$B:$M,9,FALSE),"") | U16: =_xlfn.IFNA(VLOOKUP($H16,DB!$B:$M,10,FALSE),"")
C17: 김민수 | D17: Alexa Fluor® 488 anti- mouse CD4 Antibody | I17: 1001 | J17: F | K17: Ra1 | N17: =IF(TRIM(D17)="", "", IF(N(L17)-N(M17)<=0, "X", N(L17)-N(M17))) -> X | P17: =_xlfn.IFNA(VLOOKUP($H17,DB!$B:$M,5,FALSE),"") | Q17: =_xlfn.IFNA(VLOOKUP($H17,DB!$B:$M,6,FALSE),"") | R17: =_xlfn.IFNA(VLOOKUP($H17,DB!$B:$M,7,FALSE),"") | S17: =_xlfn.IFNA(VLOOKUP($H17,DB!$B:$M,8,FALSE),"") | T17: =_xlfn.IFNA(VLOOKUP($H17,DB!$B:$M,9,FALSE),"") | U17: =_xlfn.IFNA(VLOOKUP($H17,DB!$B:$M,10,FALSE),"")
A18: 26-0125 | B18: 3/5 | C18: 김민수 | D18: Alexa Fluor® 488 anti- mouse CD4 Antibody | N18: =IF(TRIM(D18)="", "", IF(N(L18)-N(M18)<=0, "X", N(L18)-N(M18))) -> X | P18: =_xlfn.IFNA(VLOOKUP($H18,DB!$B:$M,5,FALSE),"") | Q18: =_xlfn.IFNA(VLOOKUP($H18,DB!$B:$M,6,FALSE),"") | R18: =_xlfn.IFNA(VLOOKUP($H18,DB!$B:$M,7,FALSE),"") | S18: =_xlfn.IFNA(VLOOKUP($H18,DB!$B:$M,8,FALSE),"") | T18: =_xlfn.IFNA(VLOOKUP($H18,DB!$B:$M,9,FALSE),"") | U18: =_xlfn.IFNA(VLOOKUP($H18,DB!$B:$M,10,FALSE),"")
C19: 이지 | D19: anti-mouse CD31 (PECAM-1) 100ug | E19: Aldrich | F19: 13g | G19: 333-3333-13 | H19: 3we3 | I19: 309 | J19: DF | K19: Da1 | L19: 4 | N19: =IF(TRIM(D19)="", "", IF(N(L19)-N(M19)<=0, "X", N(L19)-N(M19))) -> 4 | P19: =_xlfn.IFNA(VLOOKUP($H19,DB!$B:$M,5,FALSE),"") -> 0 | Q19: =_xlfn.IFNA(VLOOKUP($H19,DB!$B:$M,6,FALSE),"") -> 0 | R19: =_xlfn.IFNA(VLOOKUP($H19,DB!$B:$M,7,FALSE),"") -> 0 | S19: =_xlfn.IFNA(VLOOKUP($H19,DB!$B:$M,8,FALSE),"") -> 0 | T19: =_xlfn.IFNA(VLOOKUP($H19,DB!$B:$M,9,FALSE),"") -> 정보 없음 | U19: =_xlfn.IFNA(VLOOKUP($H19,DB!$B:$M,10,FALSE),"") -> 정보 없음
A20: 26-0025 | B20: 1/14 | C20: 이지 | D20: anti-mouse CD31 (PECAM-1) 100ug | E20: Aldrich | F20: 13g | G20: 333-3333-13 | H20: 3we3 | J20: DF | L20: 4 | N20: =IF(TRIM(D20)="", "", IF(N(L20)-N(M20)<=0, "X", N(L20)-N(M20))) -> 4 | P20: =_xlfn.IFNA(VLOOKUP($H20,DB!$B:$M,5,FALSE),"") -> 0 | Q20: =_xlfn.IFNA(VLOOKUP($H20,DB!$B:$M,6,FALSE),"") -> 0 | R20: =_xlfn.IFNA(VLOOKUP($H20,DB!$B:$M,7,FALSE),"") -> 0 | S20: =_xlfn.IFNA(VLOOKUP($H20,DB!$B:$M,8,FALSE),"") -> 0 | T20: =_xlfn.IFNA(VLOOKUP($H20,DB!$B:$M,9,FALSE),"") -> 정보 없음 | U20: =_xlfn.IFNA(VLOOKUP($H20,DB!$B:$M,10,FALSE),"") -> 정보 없음
A21: 26-0471 | B21: 7/21 | C21: 이정훈 | D21: benzalkonium chloride, 50wt% solution, 500 mL | N21: =IF(TRIM(D21)="", "", IF(N(L21)-N(M21)<=0, "X", N(L21)-N(M21))) -> X | P21: =_xlfn.IFNA(VLOOKUP($H21,DB!$B:$M,5,FALSE),"") | Q21: =_xlfn.IFNA(VLOOKUP($H21,DB!$B:$M,6,FALSE),"") | R21: =_xlfn.IFNA(VLOOKUP($H21,DB!$B:$M,7,FALSE),"") | S21: =_xlfn.IFNA(VLOOKUP($H21,DB!$B:$M,8,FALSE),"") | T21: =_xlfn.IFNA(VLOOKUP($H21,DB!$B:$M,9,FALSE),"") | U21: =_xlfn.IFNA(VLOOKUP($H21,DB!$B:$M,10,FALSE),"")
C22: 김영범 | D22: DMEM * 40ea | I22: 1018 | J22: DF | K22: Ra1 | N22: =IF(TRIM(D22)="", "", IF(N(L22)-N(M22)<=0, "X", N(L22)-N(M22))) -> X | P22: =_xlfn.IFNA(VLOOKUP($H22,DB!$B:$M,5,FALSE),"") | Q22: =_xlfn.IFNA(VLOOKUP($H22,DB!$B:$M,6,FALSE),"") | R22: =_xlfn.IFNA(VLOOKUP($H22,DB!$B:$M,7,FALSE),"") | S22: =_xlfn.IFNA(VLOOKUP($H22,DB!$B:$M,8,FALSE),"") | T22: =_xlfn.IFNA(VLOOKUP($H22,DB!$B:$M,9,FALSE),"") | U22: =_xlfn.IFNA(VLOOKUP($H22,DB!$B:$M,10,FALSE),"")
A23: 26-0033 | B23: 1/22 | C23: 김영범 | D23: DMEM * 40ea | N23: =IF(TRIM(D23)="", "", IF(N(L23)-N(M23)<=0, "X", N(L23)-N(M23))) -> X | P23: =_xlfn.IFNA(VLOOKUP($H23,DB!$B:$M,5,FALSE),"") | Q23: =_xlfn.IFNA(VLOOKUP($H23,DB!$B:$M,6,FALSE),"") | R23: =_xlfn.IFNA(VLOOKUP($H23,DB!$B:$M,7,FALSE),"") | S23: =_xlfn.IFNA(VLOOKUP($H23,DB!$B:$M,8,FALSE),"") | T23: =_xlfn.IFNA(VLOOKUP($H23,DB!$B:$M,9,FALSE),"") | U23: =_xlfn.IFNA(VLOOKUP($H23,DB!$B:$M,10,FALSE),"")
A24: 26-0473 | B24: 7/22 | C24: 최희선 | D24: DTSSP, 3,3'-DITHIOBIS | N24: =IF(TRIM(D24)="", "", IF(N(L24)-N(M24)<=0, "X", N(L24)-N(M24))) -> X | P24: =_xlfn.IFNA(VLOOKUP($H24,DB!$B:$M,5,FALSE),"") | Q24: =_xlfn.IFNA(VLOOKUP($H24,DB!$B:$M,6,FALSE),"") | R24: =_xlfn.IFNA(VLOOKUP($H24,DB!$B:$M,7,FALSE),"") | S24: =_xlfn.IFNA(VLOOKUP($H24,DB!$B:$M,8,FALSE),"") | T24: =_xlfn.IFNA(VLOOKUP($H24,DB!$B:$M,9,FALSE),"") | U24: =_xlfn.IFNA(VLOOKUP($H24,DB!$B:$M,10,FALSE),"")
C25: 김영범 | D25: Ezatiostat 5mg | I25: 1001 | J25: DF | K25: Ca2 | N25: =IF(TRIM(D25)="", "", IF(N(L25)-N(M25)<=0, "X", N(L25)-N(M25))) -> X | P25: =_xlfn.IFNA(VLOOKUP($H25,DB!$B:$M,5,FALSE),"") | Q25: =_xlfn.IFNA(VLOOKUP($H25,DB!$B:$M,6,FALSE),"") | R25: =_xlfn.IFNA(VLOOKUP($H25,DB!$B:$M,7,FALSE),"") | S25: =_xlfn.IFNA(VLOOKUP($H25,DB!$B:$M,8,FALSE),"") | T25: =_xlfn.IFNA(VLOOKUP($H25,DB!$B:$M,9,FALSE),"") | U25: =_xlfn.IFNA(VLOOKUP($H25,DB!$B:$M,10,FALSE),"")
A26: 26-0114 | B26: 3/17 | C26: 김영범 | D26: Ezatiostat 5mg | N26: =IF(TRIM(D26)="", "", IF(N(L26)-N(M26)<=0, "X", N(L26)-N(M26))) -> X | P26: =_xlfn.IFNA(VLOOKUP($H26,DB!$B:$M,5,FALSE),"") | Q26: =_xlfn.IFNA(VLOOKUP($H26,DB!$B:$M,6,FALSE),"") | R26: =_xlfn.IFNA(VLOOKUP($H26,DB!$B:$M,7,FALSE),"") | S26: =_xlfn.IFNA(VLOOKUP($H26,DB!$B:$M,8,FALSE),"") | T26: =_xlfn.IFNA(VLOOKUP($H26,DB!$B:$M,9,FALSE),"") | U26: =_xlfn.IFNA(VLOOKUP($H26,DB!$B:$M,10,FALSE),"")
A27: 26-0138 | B27: 3/19 | C27: 김영범 | D27: Float A lyzer * 10pk | N27: =IF(TRIM(D27)="", "", IF(N(L27)-N(M27)<=0, "X", N(L27)-N(M27))) -> X | P27: =_xlfn.IFNA(VLOOKUP($H27,DB!$B:$M,5,FALSE),"") | Q27: =_xlfn.IFNA(VLOOKUP($H27,DB!$B:$M,6,FALSE),"") | R27: =_xlfn.IFNA(VLOOKUP($H27,DB!$B:$M,7,FALSE),"") | S27: =_xlfn.IFNA(VLOOKUP($H27,DB!$B:$M,8,FALSE),"") | T27: =_xlfn.IFNA(VLOOKUP($H27,DB!$B:$M,9,FALSE),"") | U27: =_xlfn.IFNA(VLOOKUP($H27,DB!$B:$M,10,FALSE),"")
C28: 윤벼리 | D28: Gelatin from porcine skin | I28: 1001 | J28: RT | K28: Ca2 | N28: =IF(TRIM(D28)="", "", IF(N(L28)-N(M28)<=0, "X", N(L28)-N(M28))) -> X | P28: =_xlfn.IFNA(VLOOKUP($H28,DB!$B:$M,5,FALSE),"") | Q28: =_xlfn.IFNA(VLOOKUP($H28,DB!$B:$M,6,FALSE),"") | R28: =_xlfn.IFNA(VLOOKUP($H28,DB!$B:$M,7,FALSE),"") | S28: =_xlfn.IFNA(VLOOKUP($H28,DB!$B:$M,8,FALSE),"") | T28: =_xlfn.IFNA(VLOOKUP($H28,DB!$B:$M,9,FALSE),"") | U28: =_xlfn.IFNA(VLOOKUP($H28,DB!$B:$M,10,FALSE),"")
A29: 26-0060 | B29: 2/4 | C29: 윤벼리 | D29: Gelatin from porcine skin | N29: =IF(TRIM(D29)="", "", IF(N(L29)-N(M29)<=0, "X", N(L29)-N(M29))) -> X | P29: =_xlfn.IFNA(VLOOKUP($H29,DB!$B:$M,5,FALSE),"") | Q29: =_xlfn.IFNA(VLOOKUP($H29,DB!$B:$M,6,FALSE),"") | R29: =_xlfn.IFNA(VLOOKUP($H29,DB!$B:$M,7,FALSE),"") | S29: =_xlfn.IFNA(VLOOKUP($H29,DB!$B:$M,8,FALSE),"") | T29: =_xlfn.IFNA(VLOOKUP($H29,DB!$B:$M,9,FALSE),"") | U29: =_xlfn.IFNA(VLOOKUP($H29,DB!$B:$M,10,FALSE),"")
C30: 김영범 | D30: Guanidine hydrochloride | I30: 309 | J30: RT | K30: Fb1 | N30: =IF(TRIM(D30)="", "", IF(N(L30)-N(M30)<=0, "X", N(L30)-N(M30))) -> X | P30: =_xlfn.IFNA(VLOOKUP($H30,DB!$B:$M,5,FALSE),"") | Q30: =_xlfn.IFNA(VLOOKUP($H30,DB!$B:$M,6,FALSE),"") | R30: =_xlfn.IFNA(VLOOKUP($H30,DB!$B:$M,7,FALSE),"") | S30: =_xlfn.IFNA(VLOOKUP($H30,DB!$B:$M,8,FALSE),"") | T30: =_xlfn.IFNA(VLOOKUP($H30,DB!$B:$M,9,FALSE),"") | U30: =_xlfn.IFNA(VLOOKUP($H30,DB!$B:$M,10,FALSE),"")
A31: 26-0009 | B31: 1/9 | C31: 김영범 | D31: Guanidine hydrochloride | J31: RT | N31: =IF(TRIM(D31)="", "", IF(N(L31)-N(M31)<=0, "X", N(L31)-N(M31))) -> X | P31: =_xlfn.IFNA(VLOOKUP($H31,DB!$B:$M,5,FALSE),"") | Q31: =_xlfn.IFNA(VLOOKUP($H31,DB!$B:$M,6,FALSE),"") | R31: =_xlfn.IFNA(VLOOKUP($H31,DB!$B:$M,7,FALSE),"") | S31: =_xlfn.IFNA(VLOOKUP($H31,DB!$B:$M,8,FALSE),"") | T31: =_xlfn.IFNA(VLOOKUP($H31,DB!$B:$M,9,FALSE),"") | U31: =_xlfn.IFNA(VLOOKUP($H31,DB!$B:$M,10,FALSE),"")
C32: 박은영 | D32: Hydrocortisone-Water Soluble | I32: 1018 | J32: R | K32: Ra1 | M32: 1 | N32: =IF(TRIM(D32)="", "", IF(N(L32)-N(M32)<=0, "X", N(L32)-N(M32))) -> X | P32: =_xlfn.IFNA(VLOOKUP($H32,DB!$B:$M,5,FALSE),"") | Q32: =_xlfn.IFNA(VLOOKUP($H32,DB!$B:$M,6,FALSE),"") | R32: =_xlfn.IFNA(VLOOKUP($H32,DB!$B:$M,7,FALSE),"") | S32: =_xlfn.IFNA(VLOOKUP($H32,DB!$B:$M,8,FALSE),"") | T32: =_xlfn.IFNA(VLOOKUP($H32,DB!$B:$M,9,FALSE),"") | U32: =_xlfn.IFNA(VLOOKUP($H32,DB!$B:$M,10,FALSE),"")
A33: 26-0045 | B33: 1/22 | C33: 박은영 | D33: Hydrocortisone-Water Soluble | N33: =IF(TRIM(D33)="", "", IF(N(L33)-N(M33)<=0, "X", N(L33)-N(M33))) -> X | P33: =_xlfn.IFNA(VLOOKUP($H33,DB!$B:$M,5,FALSE),"") | Q33: =_xlfn.IFNA(VLOOKUP($H33,DB!$B:$M,6,FALSE),"") | R33: =_xlfn.IFNA(VLOOKUP($H33,DB!$B:$M,7,FALSE),"") | S33: =_xlfn.IFNA(VLOOKUP($H33,DB!$B:$M,8,FALSE),"") | T33: =_xlfn.IFNA(VLOOKUP($H33,DB!$B:$M,9,FALSE),"") | U33: =_xlfn.IFNA(VLOOKUP($H33,DB!$B:$M,10,FALSE),"")
C34: 최수민 | D34: ICG NHS Ester, 5 mg *1ea | F34: f | I34: 1001 | J34: F | K34: Fa1 | L34: 1 | N34: =IF(TRIM(D34)="", "", IF(N(L34)-N(M34)<=0, "X", N(L34)-N(M34))) -> 1 | P34: =_xlfn.IFNA(VLOOKUP($H34,DB!$B:$M,5,FALSE),"") | Q34: =_xlfn.IFNA(VLOOKUP($H34,DB!$B:$M,6,FALSE),"") | R34: =_xlfn.IFNA(VLOOKUP($H34,DB!$B:$M,7,FALSE),"") | S34: =_xlfn.IFNA(VLOOKUP($H34,DB!$B:$M,8,FALSE),"") | T34: =_xlfn.IFNA(VLOOKUP($H34,DB!$B:$M,9,FALSE),"") | U34: =_xlfn.IFNA(VLOOKUP($H34,DB!$B:$M,10,FALSE),"")
A35: 26-0078 | B35: 2/19 | C35: 최수민 | D35: ICG NHS Ester, 5 mg *1ea | F35: f | J35: F | L35: 1 | N35: =IF(TRIM(D35)="", "", IF(N(L35)-N(M35)<=0, "X", N(L35)-N(M35))) -> 1 | P35: =_xlfn.IFNA(VLOOKUP($H35,DB!$B:$M,5,FALSE),"") | Q35: =_xlfn.IFNA(VLOOKUP($H35,DB!$B:$M,6,FALSE),"") | R35: =_xlfn.IFNA(VLOOKUP($H35,DB!$B:$M,7,FALSE),"") | S35: =_xlfn.IFNA(VLOOKUP($H35,DB!$B:$M,8,FALSE),"") | T35: =_xlfn.IFNA(VLOOKUP($H35,DB!$B:$M,9,FALSE),"") | U35: =_xlfn.IFNA(VLOOKUP($H35,DB!$B:$M,10,FALSE),"")
A36: 26-0135 | B36: 3/26 | C36: 최희선 | D36: Isopropyl alcohol 1L *10ea | N36: =IF(TRIM(D36)="", "", IF(N(L36)-N(M36)<=0, "X", N(L36)-N(M36))) -> X | P36: =_xlfn.IFNA(VLOOKUP($H36,DB!$B:$M,5,FALSE),"") | Q36: =_xlfn.IFNA(VLOOKUP($H36,DB!$B:$M,6,FALSE),"") | R36: =_xlfn.IFNA(VLOOKUP($H36,DB!$B:$M,7,FALSE),"") | S36: =_xlfn.IFNA(VLOOKUP($H36,DB!$B:$M,8,FALSE),"") | T36: =_xlfn.IFNA(VLOOKUP($H36,DB!$B:$M,9,FALSE),"") | U36: =_xlfn.IFNA(VLOOKUP($H36,DB!$B:$M,10,FALSE),"")
A37: 26-0014 | B37: 1/13 | C37: 초오 | D37: pipet 10ml * 4 | E37: Aldrich | F37: 12g | G37: 333-3333-13 | H37: 3we3 | I37: 1018 | J37: RT | K37: Ca1 | L37: 3 | N37: =IF(TRIM(D37)="", "", IF(N(L37)-N(M37)<=0, "X", N(L37)-N(M37))) -> 3 | P37: =_xlfn.IFNA(VLOOKUP($H37,DB!$B:$M,5,FALSE),"") -> 0 | Q37: =_xlfn.IFNA(VLOOKUP($H37,DB!$B:$M,6,FALSE),"") -> 0 | R37: =_xlfn.IFNA(VLOOKUP($H37,DB!$B:$M,7,FALSE),"") -> 0 | S37: =_xlfn.IFNA(VLOOKUP($H37,DB!$B:$M,8,FALSE),"") -> 0 | T37: =_xlfn.IFNA(VLOOKUP($H37,DB!$B:$M,9,FALSE),"") -> 정보 없음 | U37: =_xlfn.IFNA(VLOOKUP($H37,DB!$B:$M,10,FALSE),"") -> 정보 없음
A38: 26-0469 | B38: 7/21 | C38: 윤벼리 | D38: Premixed TBS., 10X *2 | N38: =IF(TRIM(D38)="", "", IF(N(L38)-N(M38)<=0, "X", N(L38)-N(M38))) -> X | P38: =_xlfn.IFNA(VLOOKUP($H38,DB!$B:$M,5,FALSE),"") | Q38: =_xlfn.IFNA(VLOOKUP($H38,DB!$B:$M,6,FALSE),"") | R38: =_xlfn.IFNA(VLOOKUP($H38,DB!$B:$M,7,FALSE),"") | S38: =_xlfn.IFNA(VLOOKUP($H38,DB!$B:$M,8,FALSE),"") | T38: =_xlfn.IFNA(VLOOKUP($H38,DB!$B:$M,9,FALSE),"") | U38: =_xlfn.IFNA(VLOOKUP($H38,DB!$B:$M,10,FALSE),"")
C39: 김영범 | D39: Serotonin hydrochloride 100mg | I39: 1001 | J39: R | K39: Da1 | N39: =IF(TRIM(D39)="", "", IF(N(L39)-N(M39)<=0, "X", N(L39)-N(M39))) -> X | P39: =_xlfn.IFNA(VLOOKUP($H39,DB!$B:$M,5,FALSE),"") | Q39: =_xlfn.IFNA(VLOOKUP($H39,DB!$B:$M,6,FALSE),"") | R39: =_xlfn.IFNA(VLOOKUP($H39,DB!$B:$M,7,FALSE),"") | S39: =_xlfn.IFNA(VLOOKUP($H39,DB!$B:$M,8,FALSE),"") | T39: =_xlfn.IFNA(VLOOKUP($H39,DB!$B:$M,9,FALSE),"") | U39: =_xlfn.IFNA(VLOOKUP($H39,DB!$B:$M,10,FALSE),"")
A40: 26-0102 | B40: 3/11 | C40: 김영범 | D40: Serotonin hydrochloride 100mg | N40: =IF(TRIM(D40)="", "", IF(N(L40)-N(M40)<=0, "X", N(L40)-N(M40))) -> X | P40: =_xlfn.IFNA(VLOOKUP($H40,DB!$B:$M,5,FALSE),"") | Q40: =_xlfn.IFNA(VLOOKUP($H40,DB!$B:$M,6,FALSE),"") | R40: =_xlfn.IFNA(VLOOKUP($H40,DB!$B:$M,7,FALSE),"") | S40: =_xlfn.IFNA(VLOOKUP($H40,DB!$B:$M,8,FALSE),"") | T40: =_xlfn.IFNA(VLOOKUP($H40,DB!$B:$M,9,FALSE),"") | U40: =_xlfn.IFNA(VLOOKUP($H40,DB!$B:$M,10,FALSE),"")
...

Sheet index
A1: Room List | C1: Storage Temp. List | E1: Room | F1: Storage Temp. | G1: Cabinet
A2: 309 | C2: RT | E2: 309 | F2: RT | G2: Ca1 | H2: =E2&"_"&F2 -> 309_RT
A3: 1018 | C3: R | E3: 309 | F3: RT | G3: Ca2 | H3: =E3&"_"&F3 -> 309_RT
A4: 1001 | C4: F | E4: 309 | F4: RT | G4: Sa1 | H4: =E4&"_"&F4 -> 309_RT
C5: DF | E5: 309 | F5: F | G5: Fb1 | H5: =E5&"_"&F5 -> 309_F
E6: 309 | F6: DF | G6: Da1 | H6: =E6&"_"&F6 -> 309_DF
E7: 1018 | F7: RT | G7: Ca1 | H7: =E7&"_"&F7 -> 1018_RT
E8: 1018 | F8: RT | G8: Ca2 | H8: =E8&"_"&F8 -> 1018_RT
E9: 1018 | F9: RT | G9: Sa1 | H9: =E9&"_"&F9 -> 1018_RT
E10: 1018 | F10: F | G10: Fa1 | H10: =E10&"_"&F10 -> 1018_F
E11: 1018 | F11: DF | G11: Da1 | H11: =E11&"_"&F11 -> 1018_DF
E12: 1018 | F12: DF | G12: Db1 | H12: =E12&"_"&F12 -> 1018_DF
E13: 1018 | F13: DF | G13: Db2 | H13: =E13&"_"&F13 -> 1018_DF
E14: 1001 | F14: DF | G14: Da1 | H14: =E14&"_"&F14 -> 1001_DF
E15: 1001 | F15: RT | G15: Ca2 | H15: =E15&"_"&F15 -> 1001_RT
E16: 1001 | F16: R | G16: Ra1 | H16: =E16&"_"&F16 -> 1001_R
E17: 1001 | F17: F | G17: Fa1 | H17: =E17&"_"&F17 -> 1001_F
... E19: 309 | F19: R | G19: Ra1 | H19: =E19&"_"&F19 -> 309_R
H20: =E20&"_"&F20 -> _
H21: =E21&"_"&F21 -> _
H22: =E22&"_"&F22 -> _
H23: =E23&"_"&F23 -> _
H24: =E24&"_"&F24 -> _
H25: =E25&"_"&F25 -> _
H26: =E26&"_"&F26 -> _
H27: =E27&"_"&F27 -> _
H28: =E28&"_"&F28 -> _
H29: =E29&"_"&F29 -> _
H30: =E30&"_"&F30 -> _
H31: =E31&"_"&F31 -> _
... H1000: =E1000&"_"&F1000 -> _

Sheet DB
A1: Manufacturer | B1: Catalog No. | C1: Product Name | D1: CAS No. | E1: Storage Temp. | F1: Sensitivity | G1: Signal Word | H1: Key Hazards | I1: Detailed Hazard Classification | J1: Detail_Link | K1: SDS_Link | L1: SDS_Local_Path | M1: Revision Date
A2: Aldrich | B2: 402788 | C2: Acetaldehyde | D2: 75-07-0 | E2: R | G2: ▲ 경고 | H2: ★ 인화성, ◆ 자극성/과민성, ▼ 건강유해 | I2: H224: Extremely flammable liquid and vapor / H319: Causes serious eye irritation / H335: May cause respiratory irritation / H341: Suspected of causing genetic defects / H350: May cause cancer | J2: https://www.sigmaaldrich.com/KR/ko/product/sial/402788 | K2: https://www.sigmaaldrich.com/KR/ko/sds/aldrich/402788 | L2: 정보 없음 | M2: 46244.862
A3: Aldrich | B3: 8.02361 | C3: p-Chloranil | D3: 118-75-2 | E3: 2-30°c | G3: ▲ 경고 | H3: ● 독성, ▲ 부식성/눈손상, ◆ 자극성/과민성, ■ 환경유해 | I3: H315: Causes skin irritation / H317: May cause an allergic skin reaction / H318: Causes serious eye damage / H410: Very toxic to aquatic life with long lasting effects | J3: https://www.sigmaaldrich.com/KR/ko/product/mm/802361 | K3: https://www.sigmaaldrich.com/KR/ko/sds/aldrich/8.02361 | L3: 정보 없음 | M3: 46244.862
A4: Sigma-Aldrich | B4: 440140 | C4: (3-Aminopropyl)triethoxysilane | D4: 919-30-2 | E4: RT | F4: N/A | G4: ● 위험 | H4: ▲ 부식성/눈손상 | I4: H302: Harmful if swallowed / H314: Causes severe skin burns and eye damage / H317: May cause an allergic skin reaction | J4: https://www.sigmaaldrich.com/KR/ko/product/aldrich/440140 | K4: https://www.sigmaaldrich.com/KR/ko/sds/aldrich/440140 | L4: 정보 없음 | M4: 2026-08-10 19:00:18
A5: Sigma-Aldrich | B5: 131377 | C5: 1,10-Phenanthroline | D5: 66-71-7 | E5: RT | G5: 정보 없음 | H5: ● 독성, ■ 환경유해 | I5: H301: Toxic if swallowed / H410: Very toxic to aquatic life with long lasting effects | J5: https://www.sigmaaldrich.com/KR/ko/product/aldrich/131377 | K5: https://www.sigmaaldrich.com/KR/ko/sds/aldrich/131377 | L5: 정보 없음 | M5: 2026-08-10 20:59:31
A6: Sigma-Aldrich | B6: 909270-10G | C6: Acrylic anhydride | D6: 2051-76-5 | E6: R | G6: ▲ 경고 | H6: ◆ 자극성/과민성 | I6: H302: Harmful if swallowed / H315: Causes skin irritation / H317: May cause an allergic skin reaction / H319: Causes serious eye irritation / H335: May cause respiratory irritation | J6: https://www.sigmaaldrich.com/KR/ko/product/aldrich/909270 | K6: https://www.sigmaaldrich.com/KR/ko/sds/aldrich/909270-10G | L6: 정보 없음 | M6: 2026-08-10 21:00:17
A7: Sigma-Aldrich | B7: 803200 | C7: DTSSP (3,3′-dithiobis(sulfosuccinimidyl propionate)) | D7: 81069-02-5 | E7: R | G7: 정보 없음 | H7: 정보 없음 | I7: 정보 없음 | J7: https://www.sigmaaldrich.com/KR/en/product/aldrich/803200 | K7: https://www.sigmaaldrich.com/KR/ko/sds/aldrich/803200 | L7: 정보 없음 | M7: 2026-08-10 16:07:39
A8: Sigma-Aldrich | B8: 359238 | C8: Perfluorooctane | D8: 정보 없음 | E8: 정보 없음 | J8: https://www.sigmaaldrich.com/KR/en/product/aldrich/359238 | K8: 정보 없음 | L8: 정보 없음 | M8: 2026-08-10 15:43:12
A9: Sigma-Aldrich | B9: 8.02361 | C9: p-Chloranil | D9: 118-75-2 | E9: 2-30°c | G9: ▲ 경고 | H9: ● 독성, ▲ 부식성/눈손상, ◆ 자극성/과민성, ■ 환경유해 | I9: H315: Causes skin irritation / H317: May cause an allergic skin reaction / H318: Causes serious eye damage / H410: Very toxic to aquatic life with long lasting effects | J9: https://www.sigmaaldrich.com/KR/ko/product/mm/802361 | K9: https://www.sigmaaldrich.com/KR/ko/sds/aldrich/8.02361 | L9: 정보 없음 | M9: 2026-08-10 18:33:39
A10: Sigma-Aldrich | B10: 94884 | C10: 제조사 홈페이지에서 검색 실패 | D10: 정보 없음 | E10: 정보 없음 | J10: 정보 없음 | K10: 정보 없음 | L10: 정보 없음 | M10: 2026-08-10 15:33:23
A11: Sigma-Aldrich | B11: 3we3 | C11: 제조사 홈페이지에서 검색 실패 | D11: 정보 없음 | E11: 정보 없음 | J11: 정보 없음 | K11: 정보 없음 | L11: 정보 없음 | M11: 2026-08-10 15:33:36
A12: Sigma-Aldrich | B12: 402788 | C12: 제조사 홈페이지에서 검색 실패 | D12: 정보 없음 | E12: 정보 없음 | J12: 정보 없음 | K12: 정보 없음 | L12: 정보 없음 | M12: 2026-08-10 15:33:43
A13: TCI | B13: C0119 | C13: 1,1'-Carbonyldiimidazole | D13: 530-62-1 | E13: 정보 없음 | J13: https://www.tcichemicals.com/KR/en/p/C0119 | K13: 정보 없음 | L13: 정보 없음 | M13: 2026-08-10 15:42:47
A14: TCI | B14: T0751 | C14: Trifluoromethanesulfonic Acid | D14: 1493-13-6 | E14: 정보 없음 | J14: https://www.tcichemicals.com/KR/en/p/T0751 | K14: 정보 없음 | L14: 정보 없음 | M14: 2026-08-10 15:42:57
A15: Thermo Fisher | B15: L16400 | C15: 1,10-Phenanthroline | D15: 정보 없음 | E15: 정보 없음 | J15: https://www.thermofisher.com/order/catalog/product/L16400 | K15: https://www.thermofisher.com/search/browse/results?term=L16400 | L15: 정보 없음 | M15: 2026-08-10 15:43:25
A16: Thermo Fisher | B16: 300-13-50UG | C16: 1,10-Phenanthroline | D16: 정보 없음 | E16: 정보 없음 | J16: https://www.thermofisher.com/order/catalog/product/300-13-50UG | K16: https://www.thermofisher.com/search/browse/results?term=300-13-50UG | L16: 정보 없음 | M16: 2026-08-10 15:43:26
A17: Thermo Fisher | B17: 704060F | C17: Acrylic anhydride | D17: 정보 없음 | E17: 정보 없음 | J17: https://www.thermofisher.com/order/catalog/product/704060F | K17: https://www.thermofisher.com/search/browse/results?term=704060F | L17: 정보 없음 | M17: 2026-08-10 15:43:32
A18: Thermo Fisher | B18: A10436 | C18: Acrylic anhydride | D18: 검색 실패 | E18: 정보 없음 | F18: N/A | G18: 정보 없음 | H18: 정보 없음 | I18: 정보 없음 | J18: 정보 없음 | K18: 정보 없음 | L18: 정보 없음 | M18: 2026-08-10 21:04:00
A19: aldrich | B19: 659452 | C19: 1-Adamantanethiol | D19: 34301-54-7 | E19: RT | G19: ▲ 경고 | H19: ● 독성, ◆ 자극성/과민성 | I19: H301: Toxic if swallowed / H319: Causes serious eye irritation | J19: https://www.sigmaaldrich.com/KR/ko/product/aldrich/659452 | K19: https://www.sigmaaldrich.com/KR/ko/sds/aldrich/659452 | L19: 정보 없음 | M19: 46244.863
A20: aldrich | B20: 803200 | C20: DTSSP (3,3′-dithiobis(sulfosuccinimidyl propionate)) | D20: 81069-02-5 | E20: refrigerator (4 도) | F20: 정보 없음 | G20: 정보 없음 | H20: 정보 없음 | I20: 위험분류 정보 없음 | J20: https://www.sigmaaldrich.com/KR/en/product/aldrich/803200 | K20: https://www.sigmaaldrich.com/KR/ko/sds/aldrich/803200 | L20: C:\Users\Jeonghun Lee\.gemini\antigravity\scratch\chemical manager\sds_downloads\SDS_Aldrich_803200.pdf | M20: 2026-08-10 15:00:05
A21: 1 | B21: 1 | C21: [ab76003] Anti-MMP9 antibody [EP1254] | D21: 사용자 직접 입력 요망 | J21: 사용자 직접 입력 요망
A22: 1 | B22: 1 | C22: [ab76003] Anti-MMP9 antibody [EP1254] | D22: 사용자 직접 입력 요망 | J22: 사용자 직접 입력 요망
A23: aldrich | B23: 659452 | C23: 1-Adamantanethiol | D23: 34301-54-7 | E23: 정보 없음 | F23: N/A | G23: ▲ 경고 | H23: ● 독성, ◆ 자극성/과민성 | I23: H319: Causes serious eye irritation / H301: Toxic if swallowed | J23: https://www.sigmaaldrich.com/KR/en/product/aldrich/659452 | K23: https://www.sigmaaldrich.com/KR/ko/sds/aldrich/659452 | L23: C:\Users\Jeonghun Lee\.gemini\antigravity\scratch\chemical manager\sds\1-Adamantanethiol.pdf | M23: 46244.925
A24: Aldrich | B24: 402788 | C24: Acetaldehyde | D24: 75-07-0 | E24: R | F24: N/A | G24: ▲ 경고 | H24: ★ 인화성, ◆ 자극성/과민성, ▼ 건강유해 | I24: H319: Causes serious eye irritation / H335: May cause respiratory irritation / H341: Suspected of causing genetic defects / H350: May cause cancer / H224: Extremely flammable liquid and vapor | J24: https://www.sigmaaldrich.com/KR/en/product/sial/402788 | K24: https://www.sigmaaldrich.com/KR/ko/sds/sial/402788 | L24: C:\Users\Jeonghun Lee\.gemini\antigravity\scratch\chemical manager\sds\Acetaldehyde.pdf | M24: 46244.926
A25: Fff | B25: 2w5w | C25: [B7651] Brefeldin A | D25: 사용자 직접 입력 요망 | J25: 사용자 직접 입력 요망

Sheet Guide
A1: [ Chemical Manager 프로그램 사용 방법 및 주의사항 ]
A3: 1. 기본 동작 원리 및 저장 기준
A4: - 프로그램은 원본 Orderbook.xlsx (주문대장) 파일의 변경을 감지하여 데이터를 읽어옵니다.
A5: - 폴더 내에서 이름에 적힌 날짜/시간이 가장 최신인 ChemicalList 파일을 기준으로 삼습니다.
A6: - 업데이트 완료 시 덮어쓰기 대신 새로운 날짜/시간이 적힌 새 파일(ChemicalList_YYYYMMDD_HHMMSS)을 생성합니다.
A7: - 기존의 낡은 파일들은 안전하게 'Old Chemical List' 폴더로 자동 이동됩니다.
A9: 2. 사용자 작성 시 유의사항 (Orderbook 및 Chemical List)
A10: - 빈 줄 금지: 데이터 중간에 완전히 비어있는 줄이 있으면 데이터를 읽다가 중단될 수 있으므로 차례대로 기입하세요.
A11: - 동기화 기준: 시약명과 카탈로그 번호 등을 기준으로 기존에 등록된 시약인지 새 시약인지 판단합니다.
A12: - 수령 확인 (Status): 수령 후 Status 열에 'O' 또는 'ㅇ'을 입력하면 수령으로 간주되며, PDF 출력 필터링에 사용됩니다.
A13: - 드롭다운 선택: 캐비넷(Cabinet)은 Room과 Storage Temp.에 따라 동적으로 변하므로 잘못된 값을 억지로 쓰지 마세요.
A14: - 오더북의 "시약, 수령확인, 회사, 수량, 용량, CAS 번호, 품번, 보관온도" 열의 내용을 자동으로 동기화합니다.
... A23: - 자동 동기화 켜짐 상태에서는 Orderbook을 저장할 때마다 병합이 진행되므로, 수동 제어를 원하시면 정지 버튼을 누르세요.
