Workbook

Sheet ChemicalList
A1: Order No. | B1: Order Date | C1: Ordered By | D1: Product Name | E1: Manufacturer | F1: Package Size | G1: CAS No. | H1: Catalog No. | I1: Room | J1: Storage Temp. | K1: Cabinet | L1: Quantity | M1: Used | N1: Status | O1: Remarks | P1: Sensitivity | Q1: Signal Word | R1: Key Hazards | S1: Detailed Hazard Classification | T1: Detail_Link | U1: SDS_Link
D2: =IF(OR(E2="", H2=""), "Perfluorooctane", IFERROR(IF(VLOOKUP(E2&"|"&H2&"", DB!$A:$N, 4, FALSE)="","Perfluorooctane",VLOOKUP(E2&"|"&H2&"", DB!$A:$N, 4, FALSE)), "Perfluorooctane")) | E2: Aldrich | F2: 100 g | G2: =IF(OR(E2="", H2=""), "", IFERROR(VLOOKUP(E2&"|"&H2&"", DB!$A:$N, 5, FALSE), "")) | H2: 359238 | I2: 309 | J2: =IF(OR(E2="", H2=""), "", IFERROR(IF(VLOOKUP(E2&"|"&H2&"", DB!$A:$N, 6, FALSE)="","-",VLOOKUP(E2&"|"&H2&"", DB!$A:$N, 6, FALSE)), "-")) | K2: Ra1 | L2: 1 | N2: =IF(TRIM(D2)="", "", IF(N(L2)-N(M2)<=0, "X", N(L2)-N(M2))) | P2: =IF(OR(E2="", H2=""), "", IFERROR(IF(VLOOKUP(E2&"|"&H2&"", DB!$A:$N, 10, FALSE)="","-",VLOOKUP(E2&"|"&H2&"", DB!$A:$N, 10, FALSE)), "-")) | Q2: =IF(OR(E2="", H2=""), "", IFERROR(IF(VLOOKUP(E2&"|"&H2&"", DB!$A:$N, 7, FALSE)="","-",VLOOKUP(E2&"|"&H2&"", DB!$A:$N, 7, FALSE)), "-")) | R2: =IF(OR(E2="", H2=""), "", IFERROR(IF(VLOOKUP(E2&"|"&H2&"", DB!$A:$N, 8, FALSE)="","-",VLOOKUP(E2&"|"&H2&"", DB!$A:$N, 8, FALSE)), "-")) | S2: =IF(OR(E2="", H2=""), "", IFERROR(IF(VLOOKUP(E2&"|"&H2&"", DB!$A:$N, 9, FALSE)="","-",VLOOKUP(E2&"|"&H2&"", DB!$A:$N, 9, FALSE)), "-")) | T2: =IF(OR(E2="", H2=""), "", IFERROR(IF(VLOOKUP(E2&"|"&H2&"", DB!$A:$N, 11, FALSE)="","-",VLOOKUP(E2&"|"&H2&"", DB!$A:$N, 11, FALSE)), "-")) | U2: =IF(OR(E2="", H2=""), "", IFERROR(IF(VLOOKUP(E2&"|"&H2&"", DB!$A:$N, 12, FALSE)="","-",VLOOKUP(E2&"|"&H2&"", DB!$A:$N, 12, FALSE)), "-"))
D3: =IF(OR(E3="", H3=""), "(3-Aminopropyl)triethoxysilane", IFERROR(IF(VLOOKUP(E3&"|"&H3&"", DB!$A:$N, 4, FALSE)="","(3-Aminopropyl)triethoxysilane",VLOOKUP(E3&"|"&H3&"", DB!$A:$N, 4, FALSE)), "(3-Aminopropyl)triethoxysilane")) | E3: Aldrich | F3: 100 mL | G3: =IF(OR(E3="", H3=""), "", IFERROR(VLOOKUP(E3&"|"&H3&"", DB!$A:$N, 5, FALSE), "")) | H3: 440140 | I3: 1018 | J3: =IF(OR(E3="", H3=""), "", IFERROR(IF(VLOOKUP(E3&"|"&H3&"", DB!$A:$N, 6, FALSE)="","-",VLOOKUP(E3&"|"&H3&"", DB!$A:$N, 6, FALSE)), "-")) | K3: Fa1 | L3: 1 | N3: =IF(TRIM(D3)="", "", IF(N(L3)-N(M3)<=0, "X", N(L3)-N(M3))) | P3: =IF(OR(E3="", H3=""), "", IFERROR(IF(VLOOKUP(E3&"|"&H3&"", DB!$A:$N, 10, FALSE)="","-",VLOOKUP(E3&"|"&H3&"", DB!$A:$N, 10, FALSE)), "-")) | Q3: =IF(OR(E3="", H3=""), "", IFERROR(IF(VLOOKUP(E3&"|"&H3&"", DB!$A:$N, 7, FALSE)="","-",VLOOKUP(E3&"|"&H3&"", DB!$A:$N, 7, FALSE)), "-")) | R3: =IF(OR(E3="", H3=""), "", IFERROR(IF(VLOOKUP(E3&"|"&H3&"", DB!$A:$N, 8, FALSE)="","-",VLOOKUP(E3&"|"&H3&"", DB!$A:$N, 8, FALSE)), "-")) | S3: =IF(OR(E3="", H3=""), "", IFERROR(IF(VLOOKUP(E3&"|"&H3&"", DB!$A:$N, 9, FALSE)="","-",VLOOKUP(E3&"|"&H3&"", DB!$A:$N, 9, FALSE)), "-")) | T3: =IF(OR(E3="", H3=""), "", IFERROR(IF(VLOOKUP(E3&"|"&H3&"", DB!$A:$N, 11, FALSE)="","-",VLOOKUP(E3&"|"&H3&"", DB!$A:$N, 11, FALSE)), "-")) | U3: =IF(OR(E3="", H3=""), "", IFERROR(IF(VLOOKUP(E3&"|"&H3&"", DB!$A:$N, 12, FALSE)="","-",VLOOKUP(E3&"|"&H3&"", DB!$A:$N, 12, FALSE)), "-"))
A4: 26-0043 | B4: 1/28 | C4: 초오 | D4: [ab213480] Anti-PD-L1 antibody | G4: =IF(OR(E4="", H4=""), "", IFERROR(VLOOKUP(E4&"|"&H4&"", DB!$A:$N, 5, FALSE), "")) | I4: 1018 | K4: Ca1 | M4: 1 | N4: =IF(TRIM(D4)="", "", IF(N(L4)-N(M4)<=0, "X", N(L4)-N(M4)))
C5: 윤벼리 | D5: =IF(OR(E5="", H5=""), "[ab76003] Anti-MMP9 antibody [EP1254]", IFERROR(IF(VLOOKUP(E5&"|"&H5&"", DB!$A:$N, 4, FALSE)="","[ab76003] Anti-MMP9 antibody [EP1254]",VLOOKUP(E5&"|"&H5&"", DB!$A:$N, 4, FALSE)), "[ab76003] Anti-MMP9 antibody [EP1254]")) | E5: Aa | F5: 1 | G5: =IF(OR(E5="", H5=""), "", IFERROR(VLOOKUP(E5&"|"&H5&"", DB!$A:$N, 5, FALSE), "")) | H5: 1 | I5: 1001 | J5: =IF(OR(E5="", H5=""), "", IFERROR(IF(VLOOKUP(E5&"|"&H5&"", DB!$A:$N, 6, FALSE)="","-",VLOOKUP(E5&"|"&H5&"", DB!$A:$N, 6, FALSE)), "-")) | K5: Ca2 | L5: 2 | N5: =IF(TRIM(D5)="", "", IF(N(L5)-N(M5)<=0, "X", N(L5)-N(M5))) | P5: =IF(OR(E5="", H5=""), "", IFERROR(IF(VLOOKUP(E5&"|"&H5&"", DB!$A:$N, 10, FALSE)="","-",VLOOKUP(E5&"|"&H5&"", DB!$A:$N, 10, FALSE)), "-")) | Q5: =IF(OR(E5="", H5=""), "", IFERROR(IF(VLOOKUP(E5&"|"&H5&"", DB!$A:$N, 7, FALSE)="","-",VLOOKUP(E5&"|"&H5&"", DB!$A:$N, 7, FALSE)), "-")) | R5: =IF(OR(E5="", H5=""), "", IFERROR(IF(VLOOKUP(E5&"|"&H5&"", DB!$A:$N, 8, FALSE)="","-",VLOOKUP(E5&"|"&H5&"", DB!$A:$N, 8, FALSE)), "-")) | S5: =IF(OR(E5="", H5=""), "", IFERROR(IF(VLOOKUP(E5&"|"&H5&"", DB!$A:$N, 9, FALSE)="","-",VLOOKUP(E5&"|"&H5&"", DB!$A:$N, 9, FALSE)), "-")) | T5: =IF(OR(E5="", H5=""), "", IFERROR(IF(VLOOKUP(E5&"|"&H5&"", DB!$A:$N, 11, FALSE)="","-",VLOOKUP(E5&"|"&H5&"", DB!$A:$N, 11, FALSE)), "-")) | U5: =IF(OR(E5="", H5=""), "", IFERROR(IF(VLOOKUP(E5&"|"&H5&"", DB!$A:$N, 12, FALSE)="","-",VLOOKUP(E5&"|"&H5&"", DB!$A:$N, 12, FALSE)), "-"))
A6: 26-0057 | B6: 2/4 | C6: 윤벼리 | D6: =IF(OR(E6="", H6=""), "[ab76003] Anti-MMP9 antibody [EP1254]", IFERROR(IF(VLOOKUP(E6&"|"&H6&"", DB!$A:$N, 4, FALSE)="","[ab76003] Anti-MMP9 antibody [EP1254]",VLOOKUP(E6&"|"&H6&"", DB!$A:$N, 4, FALSE)), "[ab76003] Anti-MMP9 antibody [EP1254]")) | E6: Aa | F6: 1 | G6: =IF(OR(E6="", H6=""), "", IFERROR(VLOOKUP(E6&"|"&H6&"", DB!$A:$N, 5, FALSE), "")) | H6: 1 | J6: =IF(OR(E6="", H6=""), "", IFERROR(IF(VLOOKUP(E6&"|"&H6&"", DB!$A:$N, 6, FALSE)="","-",VLOOKUP(E6&"|"&H6&"", DB!$A:$N, 6, FALSE)), "-")) | L6: 2 | N6: =IF(TRIM(D6)="", "", IF(N(L6)-N(M6)<=0, "X", N(L6)-N(M6))) | P6: =IF(OR(E6="", H6=""), "", IFERROR(IF(VLOOKUP(E6&"|"&H6&"", DB!$A:$N, 10, FALSE)="","-",VLOOKUP(E6&"|"&H6&"", DB!$A:$N, 10, FALSE)), "-")) | Q6: =IF(OR(E6="", H6=""), "", IFERROR(IF(VLOOKUP(E6&"|"&H6&"", DB!$A:$N, 7, FALSE)="","-",VLOOKUP(E6&"|"&H6&"", DB!$A:$N, 7, FALSE)), "-")) | R6: =IF(OR(E6="", H6=""), "", IFERROR(IF(VLOOKUP(E6&"|"&H6&"", DB!$A:$N, 8, FALSE)="","-",VLOOKUP(E6&"|"&H6&"", DB!$A:$N, 8, FALSE)), "-")) | S6: =IF(OR(E6="", H6=""), "", IFERROR(IF(VLOOKUP(E6&"|"&H6&"", DB!$A:$N, 9, FALSE)="","-",VLOOKUP(E6&"|"&H6&"", DB!$A:$N, 9, FALSE)), "-")) | T6: =IF(OR(E6="", H6=""), "", IFERROR(IF(VLOOKUP(E6&"|"&H6&"", DB!$A:$N, 11, FALSE)="","-",VLOOKUP(E6&"|"&H6&"", DB!$A:$N, 11, FALSE)), "-")) | U6: =IF(OR(E6="", H6=""), "", IFERROR(IF(VLOOKUP(E6&"|"&H6&"", DB!$A:$N, 12, FALSE)="","-",VLOOKUP(E6&"|"&H6&"", DB!$A:$N, 12, FALSE)), "-"))
C7: 초오 | D7: =IF(OR(E7="", H7=""), "[B7651] Brefeldin A", IFERROR(IF(VLOOKUP(E7&"|"&H7&"", DB!$A:$N, 4, FALSE)="","[B7651] Brefeldin A",VLOOKUP(E7&"|"&H7&"", DB!$A:$N, 4, FALSE)), "[B7651] Brefeldin A")) | E7: Fff | F7: a | G7: =IF(OR(E7="", H7=""), "", IFERROR(VLOOKUP(E7&"|"&H7&"", DB!$A:$N, 5, FALSE), "")) | H7: 2w5w | I7: 1018 | J7: =IF(OR(E7="", H7=""), "", IFERROR(IF(VLOOKUP(E7&"|"&H7&"", DB!$A:$N, 6, FALSE)="","-",VLOOKUP(E7&"|"&H7&"", DB!$A:$N, 6, FALSE)), "-")) | K7: Db2 | L7: 2 | M7: 1 | N7: =IF(TRIM(D7)="", "", IF(N(L7)-N(M7)<=0, "X", N(L7)-N(M7))) | P7: =IF(OR(E7="", H7=""), "", IFERROR(IF(VLOOKUP(E7&"|"&H7&"", DB!$A:$N, 10, FALSE)="","-",VLOOKUP(E7&"|"&H7&"", DB!$A:$N, 10, FALSE)), "-")) | Q7: =IF(OR(E7="", H7=""), "", IFERROR(IF(VLOOKUP(E7&"|"&H7&"", DB!$A:$N, 7, FALSE)="","-",VLOOKUP(E7&"|"&H7&"", DB!$A:$N, 7, FALSE)), "-")) | R7: =IF(OR(E7="", H7=""), "", IFERROR(IF(VLOOKUP(E7&"|"&H7&"", DB!$A:$N, 8, FALSE)="","-",VLOOKUP(E7&"|"&H7&"", DB!$A:$N, 8, FALSE)), "-")) | S7: =IF(OR(E7="", H7=""), "", IFERROR(IF(VLOOKUP(E7&"|"&H7&"", DB!$A:$N, 9, FALSE)="","-",VLOOKUP(E7&"|"&H7&"", DB!$A:$N, 9, FALSE)), "-")) | T7: =IF(OR(E7="", H7=""), "", IFERROR(IF(VLOOKUP(E7&"|"&H7&"", DB!$A:$N, 11, FALSE)="","-",VLOOKUP(E7&"|"&H7&"", DB!$A:$N, 11, FALSE)), "-")) | U7: =IF(OR(E7="", H7=""), "", IFERROR(IF(VLOOKUP(E7&"|"&H7&"", DB!$A:$N, 12, FALSE)="","-",VLOOKUP(E7&"|"&H7&"", DB!$A:$N, 12, FALSE)), "-"))
A8: 26-0040 | B8: 1/26 | C8: 초오 | D8: =IF(OR(E8="", H8=""), "[B7651] Brefeldin A", IFERROR(IF(VLOOKUP(E8&"|"&H8&"", DB!$A:$N, 4, FALSE)="","[B7651] Brefeldin A",VLOOKUP(E8&"|"&H8&"", DB!$A:$N, 4, FALSE)), "[B7651] Brefeldin A")) | E8: Fff | F8: a | G8: =IF(OR(E8="", H8=""), "", IFERROR(VLOOKUP(E8&"|"&H8&"", DB!$A:$N, 5, FALSE), "")) | H8: 2w5w | J8: =IF(OR(E8="", H8=""), "", IFERROR(IF(VLOOKUP(E8&"|"&H8&"", DB!$A:$N, 6, FALSE)="","-",VLOOKUP(E8&"|"&H8&"", DB!$A:$N, 6, FALSE)), "-")) | L8: 2 | N8: =IF(TRIM(D8)="", "", IF(N(L8)-N(M8)<=0, "X", N(L8)-N(M8))) | P8: =IF(OR(E8="", H8=""), "", IFERROR(IF(VLOOKUP(E8&"|"&H8&"", DB!$A:$N, 10, FALSE)="","-",VLOOKUP(E8&"|"&H8&"", DB!$A:$N, 10, FALSE)), "-")) | Q8: =IF(OR(E8="", H8=""), "", IFERROR(IF(VLOOKUP(E8&"|"&H8&"", DB!$A:$N, 7, FALSE)="","-",VLOOKUP(E8&"|"&H8&"", DB!$A:$N, 7, FALSE)), "-")) | R8: =IF(OR(E8="", H8=""), "", IFERROR(IF(VLOOKUP(E8&"|"&H8&"", DB!$A:$N, 8, FALSE)="","-",VLOOKUP(E8&"|"&H8&"", DB!$A:$N, 8, FALSE)), "-")) | S8: =IF(OR(E8="", H8=""), "", IFERROR(IF(VLOOKUP(E8&"|"&H8&"", DB!$A:$N, 9, FALSE)="","-",VLOOKUP(E8&"|"&H8&"", DB!$A:$N, 9, FALSE)), "-")) | T8: =IF(OR(E8="", H8=""), "", IFERROR(IF(VLOOKUP(E8&"|"&H8&"", DB!$A:$N, 11, FALSE)="","-",VLOOKUP(E8&"|"&H8&"", DB!$A:$N, 11, FALSE)), "-")) | U8: =IF(OR(E8="", H8=""), "", IFERROR(IF(VLOOKUP(E8&"|"&H8&"", DB!$A:$N, 12, FALSE)="","-",VLOOKUP(E8&"|"&H8&"", DB!$A:$N, 12, FALSE)), "-"))
A9: 26-0038 | B9: 1/26 | C9: 초오 | D9: =IF(OR(E9="", H9=""), "[B7651] Brefeldin A", IFERROR(IF(VLOOKUP(E9&"|"&H9&"", DB!$A:$N, 4, FALSE)="","[B7651] Brefeldin A",VLOOKUP(E9&"|"&H9&"", DB!$A:$N, 4, FALSE)), "[B7651] Brefeldin A")) | E9: Fff | F9: a | G9: =IF(OR(E9="", H9=""), "", IFERROR(VLOOKUP(E9&"|"&H9&"", DB!$A:$N, 5, FALSE), "")) | H9: 2w5w | I9: 1018 | J9: =IF(OR(E9="", H9=""), "", IFERROR(IF(VLOOKUP(E9&"|"&H9&"", DB!$A:$N, 6, FALSE)="","-",VLOOKUP(E9&"|"&H9&"", DB!$A:$N, 6, FALSE)), "-")) | K9: Ca2 | L9: 2 | N9: =IF(TRIM(D9)="", "", IF(N(L9)-N(M9)<=0, "X", N(L9)-N(M9))) | P9: =IF(OR(E9="", H9=""), "", IFERROR(IF(VLOOKUP(E9&"|"&H9&"", DB!$A:$N, 10, FALSE)="","-",VLOOKUP(E9&"|"&H9&"", DB!$A:$N, 10, FALSE)), "-")) | Q9: =IF(OR(E9="", H9=""), "", IFERROR(IF(VLOOKUP(E9&"|"&H9&"", DB!$A:$N, 7, FALSE)="","-",VLOOKUP(E9&"|"&H9&"", DB!$A:$N, 7, FALSE)), "-")) | R9: =IF(OR(E9="", H9=""), "", IFERROR(IF(VLOOKUP(E9&"|"&H9&"", DB!$A:$N, 8, FALSE)="","-",VLOOKUP(E9&"|"&H9&"", DB!$A:$N, 8, FALSE)), "-")) | S9: =IF(OR(E9="", H9=""), "", IFERROR(IF(VLOOKUP(E9&"|"&H9&"", DB!$A:$N, 9, FALSE)="","-",VLOOKUP(E9&"|"&H9&"", DB!$A:$N, 9, FALSE)), "-")) | T9: =IF(OR(E9="", H9=""), "", IFERROR(IF(VLOOKUP(E9&"|"&H9&"", DB!$A:$N, 11, FALSE)="","-",VLOOKUP(E9&"|"&H9&"", DB!$A:$N, 11, FALSE)), "-")) | U9: =IF(OR(E9="", H9=""), "", IFERROR(IF(VLOOKUP(E9&"|"&H9&"", DB!$A:$N, 12, FALSE)="","-",VLOOKUP(E9&"|"&H9&"", DB!$A:$N, 12, FALSE)), "-"))
C10: 초오 | D10: [S0809.5000] Sucrose | G10: =IF(OR(E10="", H10=""), "", IFERROR(VLOOKUP(E10&"|"&H10&"", DB!$A:$N, 5, FALSE), "")) | I10: 1001 | J10: RT | K10: Da1 | N10: =IF(TRIM(D10)="", "", IF(N(L10)-N(M10)<=0, "X", N(L10)-N(M10)))
A11: 26-0049 | B11: 1/29 | C11: 초오 | D11: [S0809.5000] Sucrose | G11: =IF(OR(E11="", H11=""), "", IFERROR(VLOOKUP(E11&"|"&H11&"", DB!$A:$N, 5, FALSE), "")) | N11: =IF(TRIM(D11)="", "", IF(N(L11)-N(M11)<=0, "X", N(L11)-N(M11)))
D12: 0.1 M Disodium hydrogenphos | G12: =IF(OR(E12="", H12=""), "", IFERROR(VLOOKUP(E12&"|"&H12&"", DB!$A:$N, 5, FALSE), "")) | I12: 309 | J12: DF | K12: Da1 | L12: 1 | N12: =IF(TRIM(D12)="", "", IF(N(L12)-N(M12)<=0, "X", N(L12)-N(M12)))
D13: 0.1 M Sodium phosphate | E13: Made By Nki | G13: =IF(OR(E13="", H13=""), "", IFERROR(VLOOKUP(E13&"|"&H13&"", DB!$A:$N, 5, FALSE), "")) | I13: 1018 | J13: R | K13: Ra1 | L13: 1 | N13: =IF(TRIM(D13)="", "", IF(N(L13)-N(M13)<=0, "X", N(L13)-N(M13)))
D14: =IF(OR(E14="", H14=""), "1,1,1,2,3,4,4,5,5,5-Decafluoropentane", IFERROR(IF(VLOOKUP(E14&"|"&H14&"", DB!$A:$N, 4, FALSE)="","1,1,1,2,3,4,4,5,5,5-Decafluoropentane",VLOOKUP(E14&"|"&H14&"", DB!$A:$N, 4, FALSE)), "1,1,1,2,3,4,4,5,5,5-Decafluoropentane")) | E14: Aldrich | F14: 100 mL | G14: =IF(OR(E14="", H14=""), "", IFERROR(VLOOKUP(E14&"|"&H14&"", DB!$A:$N, 5, FALSE), "")) | H14: 94884 | I14: 309 | J14: =IF(OR(E14="", H14=""), "", IFERROR(IF(VLOOKUP(E14&"|"&H14&"", DB!$A:$N, 6, FALSE)="","-",VLOOKUP(E14&"|"&H14&"", DB!$A:$N, 6, FALSE)), "-")) | K14: Da1 | L14: 1 | N14: =IF(TRIM(D14)="", "", IF(N(L14)-N(M14)<=0, "X", N(L14)-N(M14))) | P14: =IF(OR(E14="", H14=""), "", IFERROR(IF(VLOOKUP(E14&"|"&H14&"", DB!$A:$N, 10, FALSE)="","-",VLOOKUP(E14&"|"&H14&"", DB!$A:$N, 10, FALSE)), "-")) | Q14: =IF(OR(E14="", H14=""), "", IFERROR(IF(VLOOKUP(E14&"|"&H14&"", DB!$A:$N, 7, FALSE)="","-",VLOOKUP(E14&"|"&H14&"", DB!$A:$N, 7, FALSE)), "-")) | R14: =IF(OR(E14="", H14=""), "", IFERROR(IF(VLOOKUP(E14&"|"&H14&"", DB!$A:$N, 8, FALSE)="","-",VLOOKUP(E14&"|"&H14&"", DB!$A:$N, 8, FALSE)), "-")) | S14: =IF(OR(E14="", H14=""), "", IFERROR(IF(VLOOKUP(E14&"|"&H14&"", DB!$A:$N, 9, FALSE)="","-",VLOOKUP(E14&"|"&H14&"", DB!$A:$N, 9, FALSE)), "-")) | T14: =IF(OR(E14="", H14=""), "", IFERROR(IF(VLOOKUP(E14&"|"&H14&"", DB!$A:$N, 11, FALSE)="","-",VLOOKUP(E14&"|"&H14&"", DB!$A:$N, 11, FALSE)), "-")) | U14: =IF(OR(E14="", H14=""), "", IFERROR(IF(VLOOKUP(E14&"|"&H14&"", DB!$A:$N, 12, FALSE)="","-",VLOOKUP(E14&"|"&H14&"", DB!$A:$N, 12, FALSE)), "-"))
D15: =IF(OR(E15="", H15=""), "1,10-Phenanthroline", IFERROR(IF(VLOOKUP(E15&"|"&H15&"", DB!$A:$N, 4, FALSE)="","1,10-Phenanthroline",VLOOKUP(E15&"|"&H15&"", DB!$A:$N, 4, FALSE)), "1,10-Phenanthroline")) | E15: Aldrich | F15: 5 g | G15: =IF(OR(E15="", H15=""), "", IFERROR(VLOOKUP(E15&"|"&H15&"", DB!$A:$N, 5, FALSE), "")) | H15: 131377 | I15: 1018 | J15: =IF(OR(E15="", H15=""), "", IFERROR(IF(VLOOKUP(E15&"|"&H15&"", DB!$A:$N, 6, FALSE)="","-",VLOOKUP(E15&"|"&H15&"", DB!$A:$N, 6, FALSE)), "-")) | K15: Db2 | L15: 1 | N15: =IF(TRIM(D15)="", "", IF(N(L15)-N(M15)<=0, "X", N(L15)-N(M15))) | P15: =IF(OR(E15="", H15=""), "", IFERROR(IF(VLOOKUP(E15&"|"&H15&"", DB!$A:$N, 10, FALSE)="","-",VLOOKUP(E15&"|"&H15&"", DB!$A:$N, 10, FALSE)), "-")) | Q15: =IF(OR(E15="", H15=""), "", IFERROR(IF(VLOOKUP(E15&"|"&H15&"", DB!$A:$N, 7, FALSE)="","-",VLOOKUP(E15&"|"&H15&"", DB!$A:$N, 7, FALSE)), "-")) | R15: =IF(OR(E15="", H15=""), "", IFERROR(IF(VLOOKUP(E15&"|"&H15&"", DB!$A:$N, 8, FALSE)="","-",VLOOKUP(E15&"|"&H15&"", DB!$A:$N, 8, FALSE)), "-")) | S15: =IF(OR(E15="", H15=""), "", IFERROR(IF(VLOOKUP(E15&"|"&H15&"", DB!$A:$N, 9, FALSE)="","-",VLOOKUP(E15&"|"&H15&"", DB!$A:$N, 9, FALSE)), "-")) | T15: =IF(OR(E15="", H15=""), "", IFERROR(IF(VLOOKUP(E15&"|"&H15&"", DB!$A:$N, 11, FALSE)="","-",VLOOKUP(E15&"|"&H15&"", DB!$A:$N, 11, FALSE)), "-")) | U15: =IF(OR(E15="", H15=""), "", IFERROR(IF(VLOOKUP(E15&"|"&H15&"", DB!$A:$N, 12, FALSE)="","-",VLOOKUP(E15&"|"&H15&"", DB!$A:$N, 12, FALSE)), "-"))
A16: 26-0465 | B16: 7/20 | C16: 윤벼리 | D16: Acrylamide | G16: =IF(OR(E16="", H16=""), "", IFERROR(VLOOKUP(E16&"|"&H16&"", DB!$A:$N, 5, FALSE), "")) | N16: =IF(TRIM(D16)="", "", IF(N(L16)-N(M16)<=0, "X", N(L16)-N(M16)))
C17: 김민수 | D17: Alexa Fluor® 488 anti- mouse CD4 Antibody | G17: =IF(OR(E17="", H17=""), "", IFERROR(VLOOKUP(E17&"|"&H17&"", DB!$A:$N, 5, FALSE), "")) | I17: 1001 | J17: F | K17: Ra1 | N17: =IF(TRIM(D17)="", "", IF(N(L17)-N(M17)<=0, "X", N(L17)-N(M17)))
A18: 26-0125 | B18: 3/5 | C18: 김민수 | D18: Alexa Fluor® 488 anti- mouse CD4 Antibody | G18: =IF(OR(E18="", H18=""), "", IFERROR(VLOOKUP(E18&"|"&H18&"", DB!$A:$N, 5, FALSE), "")) | N18: =IF(TRIM(D18)="", "", IF(N(L18)-N(M18)<=0, "X", N(L18)-N(M18)))
C19: 이지 | D19: =IF(OR(E19="", H19=""), "anti-mouse CD31 (PECAM-1) 100ug", IFERROR(IF(VLOOKUP(E19&"|"&H19&"", DB!$A:$N, 4, FALSE)="","anti-mouse CD31 (PECAM-1) 100ug",VLOOKUP(E19&"|"&H19&"", DB!$A:$N, 4, FALSE)), "anti-mouse CD31 (PECAM-1) 100ug")) | E19: Aldrich | F19: 13g | G19: =IF(OR(E19="", H19=""), "", IFERROR(VLOOKUP(E19&"|"&H19&"", DB!$A:$N, 5, FALSE), "")) | H19: 3we3 | I19: 309 | J19: =IF(OR(E19="", H19=""), "", IFERROR(IF(VLOOKUP(E19&"|"&H19&"", DB!$A:$N, 6, FALSE)="","-",VLOOKUP(E19&"|"&H19&"", DB!$A:$N, 6, FALSE)), "-")) | K19: Da1 | L19: 4 | N19: =IF(TRIM(D19)="", "", IF(N(L19)-N(M19)<=0, "X", N(L19)-N(M19))) | P19: =IF(OR(E19="", H19=""), "", IFERROR(IF(VLOOKUP(E19&"|"&H19&"", DB!$A:$N, 10, FALSE)="","-",VLOOKUP(E19&"|"&H19&"", DB!$A:$N, 10, FALSE)), "-")) | Q19: =IF(OR(E19="", H19=""), "", IFERROR(IF(VLOOKUP(E19&"|"&H19&"", DB!$A:$N, 7, FALSE)="","-",VLOOKUP(E19&"|"&H19&"", DB!$A:$N, 7, FALSE)), "-")) | R19: =IF(OR(E19="", H19=""), "", IFERROR(IF(VLOOKUP(E19&"|"&H19&"", DB!$A:$N, 8, FALSE)="","-",VLOOKUP(E19&"|"&H19&"", DB!$A:$N, 8, FALSE)), "-")) | S19: =IF(OR(E19="", H19=""), "", IFERROR(IF(VLOOKUP(E19&"|"&H19&"", DB!$A:$N, 9, FALSE)="","-",VLOOKUP(E19&"|"&H19&"", DB!$A:$N, 9, FALSE)), "-")) | T19: =IF(OR(E19="", H19=""), "", IFERROR(IF(VLOOKUP(E19&"|"&H19&"", DB!$A:$N, 11, FALSE)="","-",VLOOKUP(E19&"|"&H19&"", DB!$A:$N, 11, FALSE)), "-")) | U19: =IF(OR(E19="", H19=""), "", IFERROR(IF(VLOOKUP(E19&"|"&H19&"", DB!$A:$N, 12, FALSE)="","-",VLOOKUP(E19&"|"&H19&"", DB!$A:$N, 12, FALSE)), "-"))
A20: 26-0025 | B20: 1/14 | C20: 이지 | D20: =IF(OR(E20="", H20=""), "anti-mouse CD31 (PECAM-1) 100ug", IFERROR(IF(VLOOKUP(E20&"|"&H20&"", DB!$A:$N, 4, FALSE)="","anti-mouse CD31 (PECAM-1) 100ug",VLOOKUP(E20&"|"&H20&"", DB!$A:$N, 4, FALSE)), "anti-mouse CD31 (PECAM-1) 100ug")) | E20: Aldrich | F20: 13g | G20: =IF(OR(E20="", H20=""), "", IFERROR(VLOOKUP(E20&"|"&H20&"", DB!$A:$N, 5, FALSE), "")) | H20: 3we3 | I20: 309 | J20: =IF(OR(E20="", H20=""), "", IFERROR(IF(VLOOKUP(E20&"|"&H20&"", DB!$A:$N, 6, FALSE)="","-",VLOOKUP(E20&"|"&H20&"", DB!$A:$N, 6, FALSE)), "-")) | L20: 4 | N20: =IF(TRIM(D20)="", "", IF(N(L20)-N(M20)<=0, "X", N(L20)-N(M20))) | P20: =IF(OR(E20="", H20=""), "", IFERROR(IF(VLOOKUP(E20&"|"&H20&"", DB!$A:$N, 10, FALSE)="","-",VLOOKUP(E20&"|"&H20&"", DB!$A:$N, 10, FALSE)), "-")) | Q20: =IF(OR(E20="", H20=""), "", IFERROR(IF(VLOOKUP(E20&"|"&H20&"", DB!$A:$N, 7, FALSE)="","-",VLOOKUP(E20&"|"&H20&"", DB!$A:$N, 7, FALSE)), "-")) | R20: =IF(OR(E20="", H20=""), "", IFERROR(IF(VLOOKUP(E20&"|"&H20&"", DB!$A:$N, 8, FALSE)="","-",VLOOKUP(E20&"|"&H20&"", DB!$A:$N, 8, FALSE)), "-")) | S20: =IF(OR(E20="", H20=""), "", IFERROR(IF(VLOOKUP(E20&"|"&H20&"", DB!$A:$N, 9, FALSE)="","-",VLOOKUP(E20&"|"&H20&"", DB!$A:$N, 9, FALSE)), "-")) | T20: =IF(OR(E20="", H20=""), "", IFERROR(IF(VLOOKUP(E20&"|"&H20&"", DB!$A:$N, 11, FALSE)="","-",VLOOKUP(E20&"|"&H20&"", DB!$A:$N, 11, FALSE)), "-")) | U20: =IF(OR(E20="", H20=""), "", IFERROR(IF(VLOOKUP(E20&"|"&H20&"", DB!$A:$N, 12, FALSE)="","-",VLOOKUP(E20&"|"&H20&"", DB!$A:$N, 12, FALSE)), "-"))
A21: 26-0471 | B21: 7/21 | C21: 이정훈 | D21: benzalkonium chloride, 50wt% solution, 500 mL | G21: =IF(OR(E21="", H21=""), "", IFERROR(VLOOKUP(E21&"|"&H21&"", DB!$A:$N, 5, FALSE), "")) | I21: 1018 | J21: R | N21: =IF(TRIM(D21)="", "", IF(N(L21)-N(M21)<=0, "X", N(L21)-N(M21)))
C22: 김영범 | D22: DMEM * 40ea | G22: =IF(OR(E22="", H22=""), "", IFERROR(VLOOKUP(E22&"|"&H22&"", DB!$A:$N, 5, FALSE), "")) | I22: 1018 | J22: DF | K22: Ra1 | N22: =IF(TRIM(D22)="", "", IF(N(L22)-N(M22)<=0, "X", N(L22)-N(M22)))
A23: 26-0033 | B23: 1/22 | C23: 김영범 | D23: DMEM * 40ea | G23: =IF(OR(E23="", H23=""), "", IFERROR(VLOOKUP(E23&"|"&H23&"", DB!$A:$N, 5, FALSE), "")) | N23: =IF(TRIM(D23)="", "", IF(N(L23)-N(M23)<=0, "X", N(L23)-N(M23)))
A24: 26-0473 | B24: 7/22 | C24: 최희선 | D24: DTSSP, 3,3'-DITHIOBIS | G24: =IF(OR(E24="", H24=""), "", IFERROR(VLOOKUP(E24&"|"&H24&"", DB!$A:$N, 5, FALSE), "")) | N24: =IF(TRIM(D24)="", "", IF(N(L24)-N(M24)<=0, "X", N(L24)-N(M24)))
C25: 김영범 | D25: Ezatiostat 5mg | G25: =IF(OR(E25="", H25=""), "", IFERROR(VLOOKUP(E25&"|"&H25&"", DB!$A:$N, 5, FALSE), "")) | I25: 1001 | J25: DF | K25: Ca2 | N25: =IF(TRIM(D25)="", "", IF(N(L25)-N(M25)<=0, "X", N(L25)-N(M25)))
A26: 26-0114 | B26: 3/17 | C26: 김영범 | D26: Ezatiostat 5mg | G26: =IF(OR(E26="", H26=""), "", IFERROR(VLOOKUP(E26&"|"&H26&"", DB!$A:$N, 5, FALSE), "")) | N26: =IF(TRIM(D26)="", "", IF(N(L26)-N(M26)<=0, "X", N(L26)-N(M26)))
A27: 26-0138 | B27: 3/19 | C27: 김영범 | D27: Float A lyzer * 10pk | G27: =IF(OR(E27="", H27=""), "", IFERROR(VLOOKUP(E27&"|"&H27&"", DB!$A:$N, 5, FALSE), "")) | N27: =IF(TRIM(D27)="", "", IF(N(L27)-N(M27)<=0, "X", N(L27)-N(M27)))
C28: 윤벼리 | D28: Gelatin from porcine skin | G28: =IF(OR(E28="", H28=""), "", IFERROR(VLOOKUP(E28&"|"&H28&"", DB!$A:$N, 5, FALSE), "")) | I28: 1001 | J28: RT | K28: Ca2 | N28: =IF(TRIM(D28)="", "", IF(N(L28)-N(M28)<=0, "X", N(L28)-N(M28)))
A29: 26-0060 | B29: 2/4 | C29: 윤벼리 | D29: Gelatin from porcine skin | G29: =IF(OR(E29="", H29=""), "", IFERROR(VLOOKUP(E29&"|"&H29&"", DB!$A:$N, 5, FALSE), "")) | N29: =IF(TRIM(D29)="", "", IF(N(L29)-N(M29)<=0, "X", N(L29)-N(M29)))
C30: 김영범 | D30: Guanidine hydrochloride | G30: =IF(OR(E30="", H30=""), "", IFERROR(VLOOKUP(E30&"|"&H30&"", DB!$A:$N, 5, FALSE), "")) | I30: 309 | J30: RT | K30: Fb1 | N30: =IF(TRIM(D30)="", "", IF(N(L30)-N(M30)<=0, "X", N(L30)-N(M30)))
A31: 26-0009 | B31: 1/9 | C31: 김영범 | D31: Guanidine hydrochloride | G31: =IF(OR(E31="", H31=""), "", IFERROR(VLOOKUP(E31&"|"&H31&"", DB!$A:$N, 5, FALSE), "")) | J31: RT | N31: =IF(TRIM(D31)="", "", IF(N(L31)-N(M31)<=0, "X", N(L31)-N(M31)))
C32: 박은영 | D32: Hydrocortisone-Water Soluble | G32: =IF(OR(E32="", H32=""), "", IFERROR(VLOOKUP(E32&"|"&H32&"", DB!$A:$N, 5, FALSE), "")) | I32: 1018 | J32: R | K32: Ra1 | M32: 1 | N32: =IF(TRIM(D32)="", "", IF(N(L32)-N(M32)<=0, "X", N(L32)-N(M32)))
A33: 26-0045 | B33: 1/22 | C33: 박은영 | D33: Hydrocortisone-Water Soluble | G33: =IF(OR(E33="", H33=""), "", IFERROR(VLOOKUP(E33&"|"&H33&"", DB!$A:$N, 5, FALSE), "")) | N33: =IF(TRIM(D33)="", "", IF(N(L33)-N(M33)<=0, "X", N(L33)-N(M33)))
C34: 최수민 | D34: ICG NHS Ester, 5 mg *1ea | F34: f | G34: =IF(OR(E34="", H34=""), "", IFERROR(VLOOKUP(E34&"|"&H34&"", DB!$A:$N, 5, FALSE), "")) | I34: 1001 | J34: F | K34: Fa1 | L34: 1 | N34: =IF(TRIM(D34)="", "", IF(N(L34)-N(M34)<=0, "X", N(L34)-N(M34)))
A35: 26-0078 | B35: 2/19 | C35: 최수민 | D35: ICG NHS Ester, 5 mg *1ea | F35: f | G35: =IF(OR(E35="", H35=""), "", IFERROR(VLOOKUP(E35&"|"&H35&"", DB!$A:$N, 5, FALSE), "")) | J35: F | L35: 1 | N35: =IF(TRIM(D35)="", "", IF(N(L35)-N(M35)<=0, "X", N(L35)-N(M35)))
A36: 26-0135 | B36: 3/26 | C36: 최희선 | D36: Isopropyl alcohol 1L *10ea | G36: =IF(OR(E36="", H36=""), "", IFERROR(VLOOKUP(E36&"|"&H36&"", DB!$A:$N, 5, FALSE), "")) | N36: =IF(TRIM(D36)="", "", IF(N(L36)-N(M36)<=0, "X", N(L36)-N(M36)))
A37: 26-0014 | B37: 1/13 | C37: 초오 | D37: =IF(OR(E37="", H37=""), "anti-mouse CD31 (PECAM-1) 100ug", IFERROR(IF(VLOOKUP(E37&"|"&H37&"", DB!$A:$N, 4, FALSE)="","anti-mouse CD31 (PECAM-1) 100ug",VLOOKUP(E37&"|"&H37&"", DB!$A:$N, 4, FALSE)), "anti-mouse CD31 (PECAM-1) 100ug")) | E37: Aldrich | F37: 12g | G37: =IF(OR(E37="", H37=""), "", IFERROR(VLOOKUP(E37&"|"&H37&"", DB!$A:$N, 5, FALSE), "")) | H37: 3we3 | I37: 1018 | J37: =IF(OR(E37="", H37=""), "", IFERROR(IF(VLOOKUP(E37&"|"&H37&"", DB!$A:$N, 6, FALSE)="","-",VLOOKUP(E37&"|"&H37&"", DB!$A:$N, 6, FALSE)), "-")) | K37: Ca1 | L37: 3 | N37: =IF(TRIM(D37)="", "", IF(N(L37)-N(M37)<=0, "X", N(L37)-N(M37))) | P37: =IF(OR(E37="", H37=""), "", IFERROR(IF(VLOOKUP(E37&"|"&H37&"", DB!$A:$N, 10, FALSE)="","-",VLOOKUP(E37&"|"&H37&"", DB!$A:$N, 10, FALSE)), "-")) | Q37: =IF(OR(E37="", H37=""), "", IFERROR(IF(VLOOKUP(E37&"|"&H37&"", DB!$A:$N, 7, FALSE)="","-",VLOOKUP(E37&"|"&H37&"", DB!$A:$N, 7, FALSE)), "-")) | R37: =IF(OR(E37="", H37=""), "", IFERROR(IF(VLOOKUP(E37&"|"&H37&"", DB!$A:$N, 8, FALSE)="","-",VLOOKUP(E37&"|"&H37&"", DB!$A:$N, 8, FALSE)), "-")) | S37: =IF(OR(E37="", H37=""), "", IFERROR(IF(VLOOKUP(E37&"|"&H37&"", DB!$A:$N, 9, FALSE)="","-",VLOOKUP(E37&"|"&H37&"", DB!$A:$N, 9, FALSE)), "-")) | T37: =IF(OR(E37="", H37=""), "", IFERROR(IF(VLOOKUP(E37&"|"&H37&"", DB!$A:$N, 11, FALSE)="","-",VLOOKUP(E37&"|"&H37&"", DB!$A:$N, 11, FALSE)), "-")) | U37: =IF(OR(E37="", H37=""), "", IFERROR(IF(VLOOKUP(E37&"|"&H37&"", DB!$A:$N, 12, FALSE)="","-",VLOOKUP(E37&"|"&H37&"", DB!$A:$N, 12, FALSE)), "-"))
A38: 26-0469 | B38: 7/21 | C38: 윤벼리 | D38: Premixed TBS., 10X *2 | G38: =IF(OR(E38="", H38=""), "", IFERROR(VLOOKUP(E38&"|"&H38&"", DB!$A:$N, 5, FALSE), "")) | N38: =IF(TRIM(D38)="", "", IF(N(L38)-N(M38)<=0, "X", N(L38)-N(M38)))
C39: 김영범 | D39: Serotonin hydrochloride 100mg | G39: =IF(OR(E39="", H39=""), "", IFERROR(VLOOKUP(E39&"|"&H39&"", DB!$A:$N, 5, FALSE), "")) | I39: 1001 | J39: R | K39: Da1 | N39: =IF(TRIM(D39)="", "", IF(N(L39)-N(M39)<=0, "X", N(L39)-N(M39)))
A40: 26-0102 | B40: 3/11 | C40: 김영범 | D40: Serotonin hydrochloride 100mg | G40: =IF(OR(E40="", H40=""), "", IFERROR(VLOOKUP(E40&"|"&H40&"", DB!$A:$N, 5, FALSE), "")) | N40: =IF(TRIM(D40)="", "", IF(N(L40)-N(M40)<=0, "X", N(L40)-N(M40)))
...

Sheet index
A1: Room List | C1: Storage Temp. List | E1: Room | F1: Storage Temp. | G1: Cabinet
A2: 309 | C2: RT | E2: 1001 | F2: DF | G2: Da1 | H2: =E2&"_"&F2
A3: 1018 | C3: R | E3: 1001 | F3: F | G3: Fa1 | H3: =E3&"_"&F3
A4: 1001 | C4: F | E4: 1001 | F4: R | G4: Ra1 | H4: =E4&"_"&F4
C5: DF | E5: 1001 | F5: RT | G5: Ca2 | H5: =E5&"_"&F5
E6: 1018 | F6: DF | G6: Da1 | H6: =E6&"_"&F6
E7: 1018 | F7: DF | G7: Db1 | H7: =E7&"_"&F7
E8: 1018 | F8: DF | G8: Db2 | H8: =E8&"_"&F8
E9: 1018 | F9: F | G9: Fa1 | H9: =E9&"_"&F9
E10: 1018 | F10: R | G10: Ra1 | H10: =E10&"_"&F10
E11: 1018 | F11: RT | G11: Ca1 | H11: =E11&"_"&F11
E12: 1018 | F12: RT | G12: Ca2 | H12: =E12&"_"&F12
E13: 1018 | F13: RT | G13: Sa1 | H13: =E13&"_"&F13
E14: 309 | F14: DF | G14: Da1 | H14: =E14&"_"&F14
E15: 309 | F15: F | G15: Fb1 | H15: =E15&"_"&F15
E16: 309 | F16: R | G16: Ra1 | H16: =E16&"_"&F16
E17: 309 | F17: RT | G17: Ca1 | H17: =E17&"_"&F17
... E19: 309 | F19: RT | G19: Sa1 | H19: =E19&"_"&F19
H20: =E20&"_"&F20
H21: =E21&"_"&F21
H22: =E22&"_"&F22
H23: =E23&"_"&F23
H24: =E24&"_"&F24
H25: =E25&"_"&F25
H26: =E26&"_"&F26
H27: =E27&"_"&F27
H28: =E28&"_"&F28
H29: =E29&"_"&F29
H30: =E30&"_"&F30
H31: =E31&"_"&F31
... H1000: =E1000&"_"&F1000

Sheet DB
A1: Key | B1: Manufacturer | C1: Catalog No. | D1: Product Name | E1: CAS No. | F1: Storage Temp. | G1: Sensitivity | H1: Signal Word | I1: Key Hazards | J1: Detailed Hazard Classification | K1: Detail_Link | L1: SDS_Link | M1: SDS_Local_Path | N1: Revision Date
A2: =B2&"|"&C2 | B2: 1 | C2: 1 | D2: [ab76003] Anti-MMP9 antibody [EP1254] | E2: Manual Input Required | F2: - | G2: - | H2: - | I2: - | J2: - | K2: - | L2: - | M2: - | N2: 2026-08-11
A3: =B3&"|"&C3 | B3: Aa | C3: 1 | D3: [ab76003] Anti-MMP9 antibody [EP1254] | E3: Manual Input Required | F3: - | G3: - | H3: - | I3: - | J3: - | K3: - | L3: - | M3: - | N3: 2026-08-11
A4: =B4&"|"&C4 | B4: Aldrich | C4: 440140 | D4: (3-Aminopropyl)triethoxysilane | E4: 919-30-2 | F4: - | G4: - | H4: ● Danger | I4: ▲ Corrosive / Eye Damage | J4: H314: Causes severe skin burns and eye damage / H317: May cause an allergic skin reaction / H302: Harmful if swallowed | K4: https://www.sigmaaldrich.com/KR/en/product/aldrich/440140 | L4: https://www.sigmaaldrich.com/KR/ko/sds/aldrich/440140 | M4: C:\Users\Jeonghun Lee\.gemini\antigravity\scratch\chemical manager\sds\(3-Aminopropyl)triethoxysilane (Aldrich, 440140).pdf | N4: 2026-08-11
A5: =B5&"|"&C5 | B5: Aldrich | C5: 131377 | D5: 1,10-Phenanthroline | E5: 66-71-7 | F5: - | G5: - | H5: - | I5: ● Toxic, ■ Environmental Hazard | J5: H410: Very toxic to aquatic life with long lasting effects / H301: Toxic if swallowed | K5: https://www.sigmaaldrich.com/KR/en/product/aldrich/131377 | L5: https://www.sigmaaldrich.com/KR/ko/sds/aldrich/131377 | M5: C:\Users\Jeonghun Lee\.gemini\antigravity\scratch\chemical manager\sds\1,10-Phenanthroline (Aldrich, 131377).pdf | N5: 2026-08-11
A6: =B6&"|"&C6 | B6: Aldrich | C6: 659452 | D6: 1-Adamantanethiol | E6: 34301-54-7 | F6: - | G6: - | H6: ▲ Warning | I6: ● Toxic, ◆ Irritant / Sensitizer | J6: H319: Causes serious eye irritation / H301: Toxic if swallowed | K6: https://www.sigmaaldrich.com/KR/en/product/aldrich/659452 | L6: https://www.sigmaaldrich.com/KR/ko/sds/aldrich/659452 | M6: C:\Users\Jeonghun Lee\.gemini\antigravity\scratch\chemical manager\sds\1-Adamantanethiol (Aldrich, 659452).pdf | N6: 2026-08-11
A7: =B7&"|"&C7 | B7: Aldrich | C7: 402788 | D7: Acetaldehyde | E7: 75-07-0 | F7: R | G7: - | H7: ▲ Warning | I7: ★ Flammable, ◆ Irritant / Sensitizer, ▼ Health Hazard | J7: H319: Causes serious eye irritation / H335: May cause respiratory irritation / H341: Suspected of causing genetic defects / H350: May cause cancer / H224: Extremely flammable liquid and vapor | K7: https://www.sigmaaldrich.com/KR/en/product/sial/402788 | L7: https://www.sigmaaldrich.com/KR/ko/sds/sial/402788 | M7: C:\Users\Jeonghun Lee\.gemini\antigravity\scratch\chemical manager\sds\Acetaldehyde (Aldrich, 402788).pdf | N7: 2026-08-11
A8: =B8&"|"&C8 | B8: Aldrich | C8: 909270-10G | D8: Acrylic anhydride | E8: 2051-76-5 | F8: R | G8: - | H8: ▲ Warning | I8: ◆ Irritant / Sensitizer | J8: H315: Causes skin irritation / H317: May cause an allergic skin reaction / H319: Causes serious eye irritation / H335: May cause respiratory irritation / H302: Harmful if swallowed | K8: https://www.sigmaaldrich.com/KR/en/product/aldrich/909270 | L8: https://www.sigmaaldrich.com/KR/ko/sds/aldrich/909270 | M8: C:\Users\Jeonghun Lee\.gemini\antigravity\scratch\chemical manager\sds\Acrylic anhydride (Aldrich, 909270).pdf | N8: 2026-08-11
A9: =B9&"|"&C9 | B9: Aldrich | C9: 803200 | D9: DTSSP (3,3′-dithiobis(sulfosuccinimidyl propionate)) | E9: 81069-02-5 | F9: R | G9: - | H9: - | I9: - | J9: - | K9: https://www.sigmaaldrich.com/KR/en/product/aldrich/803200 | L9: https://www.sigmaaldrich.com/KR/ko/sds/aldrich/803200 | M9: C:\Users\Jeonghun Lee\.gemini\antigravity\scratch\chemical manager\sds\DTSSP (3,3′-dithiobis(sulfosuccinimidyl propionate)) (Aldrich, 803200).pdf | N9: 2026-08-11
A10: =B10&"|"&C10 | B10: Aldrich | C10: 359238 | D10: Perfluorooctane | E10: 307-34-6 | F10: - | G10: - | H10: - | I10: - | J10: - | K10: https://www.sigmaaldrich.com/KR/en/product/aldrich/359238 | L10: https://www.sigmaaldrich.com/KR/ko/sds/aldrich/359238 | M10: C:\Users\Jeonghun Lee\.gemini\antigravity\scratch\chemical manager\sds\Perfluorooctane (Aldrich, 359238).pdf | N10: 2026-08-11
A11: =B11&"|"&C11 | B11: Aldrich | C11: 94884 | D11: Search Failed | E11: N/A | F11: - | G11: - | H11: - | I11: - | J11: - | K11: - | L11: - | M11: - | N11: 2026-08-11
A12: =B12&"|"&C12 | B12: Aldrich | C12: 3we3 | D12: Search Failed | E12: N/A | F12: - | G12: - | H12: - | I12: - | J12: - | K12: - | L12: - | M12: - | N12: 2026-08-11
A13: =B13&"|"&C13 | B13: Aldrich | C13: 8.02361 | D13: p-Chloranil | E13: 118-75-2 | F13: RT | G13: - | H13: ▲ Warning | I13: ● Toxic, ▲ Corrosive / Eye Damage, ◆ Irritant / Sensitizer, ■ Environmental Hazard | J13: H317: May cause an allergic skin reaction / H318: Causes serious eye damage / H410: Very toxic to aquatic life with long lasting effects / H315: Causes skin irritation | K13: https://www.sigmaaldrich.com/KR/en/product/mm/802361 | L13: https://www.sigmaaldrich.com/KR/ko/sds/mm/8.02361 | M13: C:\Users\Jeonghun Lee\.gemini\antigravity\scratch\chemical manager\sds\p-Chloranil (Aldrich, 8.02361).pdf | N13: 2026-08-11
... A17: =B17&"|"&C17 | B17: ThermoFisher | C17: A10436 | D17: Alexa Fluor™ 488 Hydrazide | E17: N/A | F17: RT | G17: - | H17: - | I17: - | J17: - | K17: https://www.thermofisher.com/order/catalog/product/A10436 | L17: https://documents.thermofisher.com/TFS-Assets/LSG/SDS/A10436_MTR-NALT_EN.pdf | M17: C:\Users\Jeonghun Lee\.gemini\antigravity\scratch\chemical manager\sds\Alexa Fluor™ 488 Hydrazide (ThermoFisher, A10436).pdf | N17: 2026-08-11

Sheet Guide
A1: [ Chemical Manager Program User Guide & Instructions ]
A3: 1. 기본 동작 원리 및 저장 기준
A4: - 프로그램은 원본 Orderbook.xlsx (주문대장) 파일의 변경을 감지하여 데이터를 읽어옵니다.
A5: - 폴더 내에서 이름에 적힌 날짜/시간이 가장 최신인 ChemicalList 파일을 기준으로 삼습니다.
A6: - 업데이트 완료 시 덮어쓰기 대신 새로운 날짜/시간이 적힌 새 파일(ChemicalList_YYYYMMDD_HHMMSS)을 생성합니다.
A7: - 기존의 낡은 파일들은 안전하게 'Old Chemical List' 폴더로 자동 이동됩니다.
A9: 2. 사용자 작성 시 유의사항 (Orderbook 및 Chemical List)
A10: - 빈 줄 금지: 데이터 중간에 완전히 비어있는 줄이 있으면 데이터를 읽다가 중단될 수 있으므로 차례대로 기입하세요.
A11: - 동기화 기준: 시약명과 카탈로그 번호 등을 기준으로 기존에 등록된 시약인지 새 시약인지 판단합니다.
A12: - 수령 확인 (Status): 수령 후 Status 열에 'O' 또는 'ㅇ'을 입력하면 수령으로 간주되며, PDF 출력 필터링에 사용됩니다.
A13: - 드롭다운 선택: 캐비넷(Cabinet)은 Room과 Storage Temp.에 따라 동적으로 변하므로 잘못된 값을 억지로 쓰지 마세요.
A14: - 오더북의 "시약, 수령확인, 회사, 수량, 용량, CAS 번호, 품번, 보관온도" 열의 내용을 자동으로 동기화합니다.
... A23: - 자동 동기화 켜짐 상태에서는 Orderbook을 저장할 때마다 병합이 진행되므로, 수동 제어를 원하시면 정지 버튼을 누르세요.
